Workbook

Sheet Summary
B1: Ceilings Unlimited
B2: 2 Devonport Road
B3: Tauranga
B5: 45853
B7: Summary
B8: Clarifications:
B9: * CBC to provide - Mezz double height scaffold and stairs. All other access allowed.
B10: * Pricing is based on all materials being lifted/removed via crane or hiab to respective Levels to an access point/loadin platform then through facade. Removal/reinstatement of facade as well as Crane/Hiab, Access point/loadin platform to be provided by main contractor along with any associated Traffic Management costs that may be required. | D10: Pre load Floors where possible by end of January 2026
B11: * This trade pricing is based on the acceptance as a package and if individual trades were selected we would need to be contacted to discuss before acceptance.
B12: * We have included Provisional Sum for PS1 Steel Stud Partition Design (Excluded Design of Timber Partitions) a s well as Monitoring and PS4 Sign Off. | D12: PS1 Ceiling Design to be updated between CBC and Comfortech
B14: * No allowance for detailed drawings/shop drawings, resource and consent fees etc. By Others if Required. | D14: PS1 Ceiling Design and Seel Stud Partition Design to Serve as Shop Drawing
B15: * No allownce for samples of products.
B16: * Allowed for works within normal works hours Monday to Friday 7.30am - 5pm.
B17: * Rubbish disposal and system to be provided by main contractor on each Level.
B18: * No allowance for Passive Fire to all service penetrations to wall and ceiling penetrations. To be carried out by associated service contractor of specific Passive Fire Contractor.
B19: * No allowance to Fire Rate any steel work outside of what is incapsulated with walls beneath it. Understand balance of Steel work will be Intumescent Painted by others.
B20: * Interface to intumescent paint not allowed if we have to connect to Intumescent painted Steel. This needs to be clarified by fire engineer and if required treated as a variation.
B21: * No allowance for any timber framing (including timber framed bulkheads), strapping and nogging. By Others.
B22: * We have allowed for a bulkhead in Steel Stud to take perimeter pelmet to ceilings. No allowance for any other bulkheads as we understand these are timber.
B24: * Level 4 Stopping allowed.
B25: * No allowance for any Korok or Gib to associated head detail, by others.
B26: * We have allowed Concealed Grid and Steel Stud from SRP/Studco
B27: * No allowance for any windows or doors including internal glazing/partitioning.
... B52: * Pricing validity strictly as per cover letter. No allowance for cost escalations.
B56: ='Suspended Ceilings_25_8'!B9 -> Suspended Ceiling (1500 x 600) | D56: ='Suspended Ceilings_25_8'!M371 -> 628565
B58: Timber Partitions & Strapping/Nogging | D58: Nil, By Others (CBC)
B60: ='Steel Stud Partitions_25_8'!B9 -> Steel Stud Partitions | D60: ='Steel Stud Partitions_25_8'!M129 -> 111772
B62: Head Track and Gib Packing to Timber Walls (Timber Partitions by Others) | D62: Nil, By Others (CBC)
B64: ='Gib Linings_25_8'!B9 -> Gib Wall and Ceiling Linings | D64: ='Gib Linings_25_8'!M599 -> 469562
B66: =Stopping_25_8!B9 -> Gib Stopping | D66: =Stopping_25_8!M216 -> 203482
B68: Featurecraft Interior Lining | D68: Nil at this Stage as Discussed with Kenny
B70: Aluminium and Timber Skirting | D70: ='Skirting with Columns'!M112 -> 40195
B72: ='PROV SUM PS1 & PS4 _25_8'!B9 -> PROVISIONAL SUM: PS1 Design & PS4 Certificate for Interior Steel Stud Partition | D72: ='PROV SUM PS1 & PS4 _25_8'!M42 -> 12000
B74: PROVISIONAL SUM: Ceiling Seismic Components | D74: As per Provided PS1
B77: Total of all items priced | E77: =SUM(D56:D74) -> 1465576 | H77: 1465591 | J77: =H77-E77 -> 15
B78: * No allowance for GST
D81: =B56 -> Suspended Ceiling (1500 x 600) | E81: =B58 -> Timber Partitions & Strapping/Nogging | F81: =B60 -> Steel Stud Partitions | G81: =B62 -> Head Track and Gib Packing to Timber Walls (Timber Partitions by Others) | H81: =B64 -> Gib Wall and Ceiling Linings | I81: =B66 -> Gib Stopping | J81: =B68 -> Featurecraft Interior Lining | K81: =B70 -> Aluminium and Timber Skirting | L81: =B72 -> PROVISIONAL SUM: PS1 Design & PS4 Certificate for Interior Steel Stud Partition | M81: =B74 -> PROVISIONAL SUM: Ceiling Seismic Components | N81: TTL
B83: ='Suspended Ceilings_25_8'!B357 -> P&G - Admin / Supervision | D83: ='Suspended Ceilings_25_8'!M357 -> 31544.767 | E83: By CBC | F83: ='Steel Stud Partitions_25_8'!M115 -> 5540.8524 | G83: By CBC | H83: ='Gib Linings_25_8'!M585 -> 23360.861 | I83: =Stopping_25_8!M202 -> 9894.2994 | J83: TBA | K83: ='Skirting with Columns'!M98 -> 2004.0345 | L83: ='PROV SUM PS1 & PS4 _25_8'!M27 -> 594.84 | N83: =SUM(D83:M83) -> 72939.654 | P83: 7 months for bulk except 4/5/6 tenanant ceilings
B85: ='Suspended Ceilings_25_8'!B359 -> P&G - Site Establishment | D85: ='Suspended Ceilings_25_8'!M359 -> 15772.383 | F85: ='Steel Stud Partitions_25_8'!M117 -> 2770.4262 | H85: ='Gib Linings_25_8'!M587 -> 11680.43 | I85: =Stopping_25_8!M204 -> 4947.1497 | K85: ='Skirting with Columns'!M100 -> 1002.0173 | L85: ='PROV SUM PS1 & PS4 _25_8'!M29 -> 0 | N85: =SUM(D85:M85) -> 36172.407 | P85: =SUM(N83:N85) -> 109112.06
B87: ='Suspended Ceilings_25_8'!B361 -> P&G - Access Equip | D87: ='Suspended Ceilings_25_8'!M361 -> 2628.7306 | F87: ='Steel Stud Partitions_25_8'!M119 -> 461.7377 | H87: ='Gib Linings_25_8'!M589 -> 1946.7384 | I87: =Stopping_25_8!M206 -> 824.52495 | K87: ='Skirting with Columns'!M102 -> 167.00288 | L87: ='PROV SUM PS1 & PS4 _25_8'!M31 -> 0 | N87: =SUM(D87:M87) -> 6028.7345
...

Sheet Suspended Ceilings_25_8
B1: =Summary!B1 -> Ceilings Unlimited
B2: =Summary!B2 -> 2 Devonport Road
B3: =Summary!B3 -> Tauranga
B6: 45853
B9: Suspended Ceiling (1500 x 600)
Q10: =SUM(C17,C35,C76,C143,C183,C225,C269,C311) -> 988
H11: 50 | Q11: =SUM(C18,C36,C77,C144,C184,C226,C270,C312) -> 1376
A12: Item | B12: Description | C12: Qty | D12: Unit | E12: Constant | F12: Constant X Unit = Total HRS | G12: $ Lab per Unit | H12: Total Labour | I12: Materials per Unit | J12: Total Materials | K12: Total Labour & Materials | L12: Total Labour & Materials Per Unit | M12: Total | N12: % Complete | O12: Claim
B15: Basement:
B16: Concealed Grid:
B17: (CS01) Concealed Grid @ 600 crs | C17: 96 | D17: m2 | E17: 0.32 | F17: =C17*E17 -> 30.72 | G17: =$H$11*E17 -> 16 | H17: =F17*$H$11 -> 1536 | I17: 15.51 | J17: =C17*I17 -> 1488.96 | K17: =SUM(H17,J17) -> 3024.96 | L17: =K17/C17 -> 31.51 | M17: =C17*L17 -> 3024.96 | N17: 0 | O17: =M17*N17 -> 0
B18: Perimeter to Above | C18: 166 | D18: m
B20: (CS12) Fire Rated Ceiling | C20: Nil, By Others
B22: (WA24) Fire Rated Ceiling | C22: Korok, By Others
B24: (CS52) | C24: Soffit, By Others
B26: Bulkheads:
B27: (CS12) Fire Rated Bulkhead (1500) | C27: 6 | D27: m | F27: =C27*E27 -> 0 | G27: =$H$11*E27 -> 0 | H27: =F27*$H$11 -> 0 | J27: =C27*I27 -> 0 | K27: =SUM(H27,J27) -> 0 | L27: =K27/C27 -> 0 | M27: =C27*L27 -> 0 | N27: 0 | O27: =M27*N27 -> 0
B29: (WA24) | C29: Korok, By Others
P30: =SUM(M13:M26) -> 3024.96 | Q30: =P30*SUM($L$357:$L$363) -> 287.3712
P31: =P30/$M$354 -> 0.0057536517 | Q31: =P31*$M$365 -> 36.318495 | R31: =SUM(P30,Q30,Q31) -> 3348.6497 | S31: =R31*1.08 -> 3616.5417
B33: Ground:
B34: Concealed Grid:
B35: (CS01) Concealed Grid @ 600 crs | C35: 267 | D35: m2 | E35: 0.32 | F35: =C35*E35 -> 85.44 | G35: =$H$11*E35 -> 16 | H35: =F35*$H$11 -> 4272 | I35: 15.51 | J35: =C35*I35 -> 4141.17 | K35: =SUM(H35,J35) -> 8413.17 | L35: =K35/C35 -> 31.51 | M35: =C35*L35 -> 8413.17 | N35: 0 | O35: =M35*N35 -> 0
B36: Perimeter to Above | C36: 302 | D36: m
B38: (CS10) | C38: Timber Structure, By Others
B40: (CS11) | C40: Korok, By Others
B42: (CL50) | C42: Timber Structure, By Others
B44: Bulkheads:
B46: Type 2 Bulkhead @ 0.9m | C46: 16 | D46: m | E46: 0.35 | F46: =C46*E46 -> 5.6 | G46: =$H$11*E46 -> 17.5 | H46: =F46*$H$11 -> 280 | I46: 39.2 | J46: =C46*I46 -> 627.2 | K46: =SUM(H46,J46) -> 907.2 | L46: =K46/C46 -> 56.7 | M46: =C46*L46 -> 907.2 | N46: 0 | O46: =M46*N46 -> 0
B47: Bracket to Grid | C47: =C46/1.2 -> 13.333333 | D47: no | E47: 0.09 | F47: =C47*E47 -> 1.2 | G47: =$H$11*E47 -> 4.5 | H47: =F47*$H$11 -> 60 | I47: 5.28 | J47: =C47*I47 -> 70.4 | K47: =SUM(H47,J47) -> 130.4 | L47: =K47/C47 -> 9.78 | M47: =C47*L47 -> 130.4 | N47: 0 | O47: =M47*N47 -> 0
B48: Bracket to Soffit | C48: =C46/2.4 -> 6.6666667 | D48: no | E48: 0 | F48: =C48*E48 -> 0 | G48: =$H$11*E48 -> 0 | H48: =F48*$H$11 -> 0 | I48: 5.28 | J48: =C48*I48 -> 35.2 | K48: =SUM(H48,J48) -> 35.2 | L48: =K48/C48 -> 5.28 | M48: =C48*L48 -> 35.2 | N48: 0 | O48: =M48*N48 -> 0
B49: Longitudinal | C49: 7 | D49: no | E49: 0.25 | F49: =C49*E49 -> 1.75 | G49: =$H$11*E49 -> 12.5 | H49: =F49*$H$11 -> 87.5 | I49: 17.05 | J49: =C49*I49 -> 119.35 | K49: =SUM(H49,J49) -> 206.85 | L49: =K49/C49 -> 29.55 | M49: =C49*L49 -> 206.85 | N49: 0 | O49: =M49*N49 -> 0
B50: Lateral | C50: 7 | D50: no | E50: 0.12 | F50: =C50*E50 -> 0.84 | G50: =$H$11*E50 -> 6 | H50: =F50*$H$11 -> 42 | I50: 8.06 | J50: =C50*I50 -> 56.42 | K50: =SUM(H50,J50) -> 98.42 | L50: =K50/C50 -> 14.06 | M50: =C50*L50 -> 98.42 | N50: 0 | O50: =M50*N50 -> 0
B52: Type 2 Bulkhead @ 1.2m | C52: 26 | D52: m | E52: 0.25 | F52: =C52*E52 -> 6.5 | G52: =$H$11*E52 -> 12.5 | H52: =F52*$H$11 -> 325 | I52: 24.31 | J52: =C52*I52 -> 632.06 | K52: =SUM(H52,J52) -> 957.06 | L52: =K52/C52 -> 36.81 | M52: =C52*L52 -> 957.06 | N52: 0 | O52: =M52*N52 -> 0
B53: Bracket to Grid | C53: =C52/1.2 -> 21.666667 | D53: no | E53: 0.09 | F53: =C53*E53 -> 1.95 | G53: =$H$11*E53 -> 4.5 | H53: =F53*$H$11 -> 97.5 | I53: 5.28 | J53: =C53*I53 -> 114.4 | K53: =SUM(H53,J53) -> 211.9 | L53: =K53/C53 -> 9.78 | M53: =C53*L53 -> 211.9 | N53: 0 | O53: =M53*N53 -> 0
B54: Bracket to Soffit | C54: =C52/2.4 -> 10.833333 | D54: no | E54: 0 | F54: =C54*E54 -> 0 | G54: =$H$11*E54 -> 0 | H54: =F54*$H$11 -> 0 | I54: 5.28 | J54: =C54*I54 -> 57.2 | K54: =SUM(H54,J54) -> 57.2 | L54: =K54/C54 -> 5.28 | M54: =C54*L54 -> 57.2 | N54: 0 | O54: =M54*N54 -> 0
B55: Longitudinal | C55: 7 | D55: no | E55: 0.25 | F55: =C55*E55 -> 1.75 | G55: =$H$11*E55 -> 12.5 | H55: =F55*$H$11 -> 87.5 | I55: 17.05 | J55: =C55*I55 -> 119.35 | K55: =SUM(H55,J55) -> 206.85 | L55: =K55/C55 -> 29.55 | M55: =C55*L55 -> 206.85 | N55: 0 | O55: =M55*N55 -> 0
B56: Lateral | C56: 7 | D56: no | E56: 0.12 | F56: =C56*E56 -> 0.84 | G56: =$H$11*E56 -> 6 | H56: =F56*$H$11 -> 42 | I56: 8.06 | J56: =C56*I56 -> 56.42 | K56: =SUM(H56,J56) -> 98.42 | L56: =K56/C56 -> 14.06 | M56: =C56*L56 -> 98.42 | N56: 0 | O56: =M56*N56 -> 0
B58: Type 2 Bulkhead @ 1.4m | C58: 17 | D58: m | E58: 0.35 | F58: =C58*E58 -> 5.95 | G58: =$H$11*E58 -> 17.5 | H58: =F58*$H$11 -> 297.5 | I58: 41.58 | J58: =C58*I58 -> 706.86 | K58: =SUM(H58,J58) -> 1004.36 | L58: =K58/C58 -> 59.08 | M58: =C58*L58 -> 1004.36 | N58: 0 | O58: =M58*N58 -> 0
B59: Bracket to Grid | C59: =C58/1.2 -> 14.166667 | D59: no | E59: 0.09 | F59: =C59*E59 -> 1.275 | G59: =$H$11*E59 -> 4.5 | H59: =F59*$H$11 -> 63.75 | I59: 5.28 | J59: =C59*I59 -> 74.8 | K59: =SUM(H59,J59) -> 138.55 | L59: =K59/C59 -> 9.78 | M59: =C59*L59 -> 138.55 | N59: 0 | O59: =M59*N59 -> 0
...

Sheet Workings_Ceilings
AB4: ***POST APRIL*** | AM4: ***POST APRIL***
N5: Armstrong | Y5: Armstrong | AJ5: Armstrong
B6: Job Name
B7: total sqm | C7: 5337 | D7: m2 | F7: Standard grid | H7: 5% Freight | N7: Job Name | Y7: Job Name | AJ7: Job Name
B8: Cost Plus Margin | F8: Nett cost | G8: Comfortech | H8: 10% waste | N8: total sqm | O8: 5337 | P8: m2 | R8: Standard grid | T8: 5% Freight | Y8: total sqm | Z8: 5337 | AA8: m2 | AC8: Standard grid | AE8: 5% Freight | AJ8: total sqm | AK8: 5337 | AL8: m2 | AN8: Standard grid | AP8: 5% Freight
B9: admin | F9: Wall angle | G9: 2.12 | H9: =G9*1.15 -> 2.438 | N9: Cost Plus Margin | R9: Nett cost | T9: 10% waste | Y9: Cost Plus Margin | AC9: Nett cost | AE9: 10% waste | AJ9: Cost Plus Margin | AN9: Nett cost | AP9: 10% waste
B10: hourly rate | C10: 55 | F10: Mains | G10: 2.89 | H10: =G10*1.15 -> 3.3235 | N10: admin | R10: Wall angle | S10: 2.12 | T10: =S10*1.15 -> 2.438 | Y10: admin | AC10: Wall angle | AD10: 2.2 | AE10: =AD10*1.15 -> 2.53 | AJ10: admin | AN10: Wall angle | AO10: 2.2 | AP10: =AO10*1.15 -> 2.53
B11: wall trim | C11: 1467 | D11: m | F11: 1200 Nogs | G11: 2.62 | H11: =G11*1.15 -> 3.013 | N11: hourly rate | O11: 55 | R11: Mains | S11: 2.89 | T11: =S11*1.15 -> 3.3235 | Y11: hourly rate | Z11: 55 | AC11: Mains | AD11: 3.01 | AE11: =AD11*1.15 -> 3.4615 | AJ11: hourly rate | AK11: 55 | AN11: Mains | AO11: 3 | AP11: =AO11*1.15 -> 3.45
B12: tile type | C12: Tonga Eurocoustic | N12: wall trim | O12: 1224 | P12: m | R12: 1500 Nogs | S12: 3.53 | T12: =S12*1.15 -> 4.0595 | Y12: wall trim | Z12: 1224 | AA12: m | AC12: 1500 Nogs | AD12: 3.67 | AE12: =AD12*1.15 -> 4.2205 | AJ12: wall trim | AK12: 1224 | AL12: m | AN12: 1500 Nogs | AO12: 3.36 | AP12: =AO12*1.15 -> 3.864
B13: tile price | C13: =K17 -> 22.636897 | D13: per tile | F13: **WHITE GRID | I13: $19.63 per tile | N13: tile type | O13: Eurocoustic Tonga white | Y13: tile type | Z13: Eurocoustic Tonga white | AJ13: tile type | AK13: Eurocoustic Tonga white
B14: Module | C14: 1200 x 600 | I14: tiles plus 15% | K14: 1191 | N14: tile price | O14: =W20 -> 31.689713 | P14: per tile | R14: Berc Clips | S14: 1.97 | T14: =S14*1.15 -> 2.2655 | Y14: tile price | Z14: =AH20 -> 34.360877 | AA14: per tile | AC14: Berc Clips | AD14: 1.97 | AE14: =AD14*1.15 -> 2.2655 | AJ14: tile price | AK14: =AS20 -> 32.693929 | AL14: per tile | AN14: Berc Clips | AO14: 1.97 | AP14: =AO14*1.15 -> 2.2655
I15: 8525 | N15: Module | O15: 1500 x 600 | Y15: Module | Z15: 1500 x 600 | AJ15: Module | AK15: 1500 x 600
I16: 711 boxes @ $236 | K16: 167796 | U16: $26.02 per tile | AF16: $28.28 per tile | AQ16: $28.28 per tile plus 5% Freight $29.69
B17: Total Cost | C17: =C7*C36 -> 316331.26 | K17: =K16/C32 -> 22.636897 | U17: tiles plus 15% | AF17: tiles plus 15% | AQ17: tiles plus 10% wastage
B18: Total Revenue | C18: =C17*(1+C8) -> 316331.26 | D18: Price | N18: Total Cost | O18: =O8*O38 -> 336794.89 | U18: 7191 | Y18: Total Cost | Z18: =Z8*Z38 -> 354819.54 | AF18: 7191 | AJ18: Total Cost | AK18: =AK8*AK38 -> 341466.01 | AQ18: 6523 | AR18: 653 boxes
B19: Profit | C19: =C18-C17 -> 0 | N19: Total Revenue | O19: =O18*(1+O9) -> 336794.89 | P19: Price | U19: 720 boxes @ $261 | W19: 187920 | Y19: Total Revenue | Z19: =Z18*(1+Z9) -> 354819.54 | AA19: Price | AF19: 720 boxes @ $283 | AH19: 203760 | AJ19: Total Revenue | AK19: =AK18*(1+AK9) -> 341466.01 | AL19: Price | AQ19: 653 boxes @ $296.90 | AS19: 193875
N20: Profit | O20: =O19-O18 -> 0 | W20: =W19/O34 -> 31.689713 | Y20: Profit | Z20: =Z19-Z18 -> 0 | AH20: =AH19/Z34 -> 34.360877 | AJ20: Profit | AK20: =AK19-AK18 -> 0 | AS20: =AS19/AK34 -> 32.693929
B21: Standard grid
B22: USG | E22: Waste 10% on product include in cost | N22: Standard grid | Y22: Standard grid | AJ22: Standard grid
B23: Adminstration | E23: COST | F23: =SUM(C9) -> 0 | G23: HOURS | H23: COST | I23: =C10 -> 55 | N23: Peakform | Q23: Waste 10% on product include in cost | Y23: Peakform | AB23: Waste 10% on product include in cost | AJ23: Peakform | AM23: Waste 10% on product include in cost
B24: MT45 3600 | C24: =C11 -> 1467 | D24: m | E24: =H9 -> 2.438 | F24: =C24*E24 -> 3576.546 | G24: =C24/10 -> 146.7 | H24: =G24*$I$23 -> 8068.5 | N24: Adminstration | Q24: COST | R24: =SUM(O10) -> 0 | S24: HOURS | T24: COST | U24: =O11 -> 55 | Y24: Adminstration | AB24: COST | AC24: =SUM(Z10) -> 0 | AD24: HOURS | AE24: COST | AF24: =Z11 -> 55 | AJ24: Adminstration | AM24: COST | AN24: =SUM(AK10) -> 0 | AO24: HOURS | AP24: COST | AQ24: =AK11 -> 55
B25: DX3600 | C25: =C7*90% -> 4803.3 | D25: m | E25: =H10 -> 3.3235 | F25: =C25*E25 -> 15963.768 | G25: =C25/23 -> 208.83913 | H25: =G25*$I$23 -> 11486.152 | N25: BPT1932H | O25: =O12 -> 1224 | P25: m | Q25: =T10 -> 2.438 | R25: =O25*Q25 -> 2984.112 | S25: =O25/10 -> 122.4 | T25: =S25*$U$24 -> 6732 | Y25: BPT1932H | Z25: =Z12 -> 1224 | AA25: m | AB25: =AE10 -> 2.53 | AC25: =Z25*AB25 -> 3096.72 | AD25: =Z25/10 -> 122.4 | AE25: =AD25*$U$24 -> 6732 | AJ25: BPT1932H | AK25: =AK12 -> 1224 | AL25: m | AM25: =AP10 -> 2.53 | AN25: =AK25*AM25 -> 3096.72 | AO25: =AK25/10 -> 122.4 | AP25: =AO25*$U$24 -> 6732
B26: DX1200 | C26: =C7*180% -> 9606.6 | D26: m | E26: =H11 -> 3.013 | F26: =C26*E26 -> 28944.686 | G26: =C26/23 -> 417.67826 | H26: =G26*$I$23 -> 22972.304 | N26: BP734042P | O26: =(O8/1.5)*1.07 -> 3807.06 | P26: m | Q26: =T11 -> 3.3235 | R26: =O26*Q26 -> 12652.764 | S26: =O26/23 -> 165.52435 | T26: =S26*$U$24 -> 9103.8391 | Y26: BP734042P | Z26: =(Z8/1.5)*1.07 -> 3807.06 | AA26: m | AB26: =AE11 -> 3.4615 | AC26: =Z26*AB26 -> 13178.138 | AD26: =Z26/23 -> 165.52435 | AE26: =AD26*$U$24 -> 9103.8391 | AJ26: BP734042P | AK26: =(AK8/1.5)*1.07 -> 3807.06 | AL26: m | AM26: =AP11 -> 3.45 | AN26: =AK26*AM26 -> 13134.357 | AO26: =AK26/23 -> 165.52435 | AP26: =AO26*$U$24 -> 9103.8391
B27: Wire | C27: =ROUND(C7/200, 0) -> 27 | D27: ea | E27: 100 | F27: =C27*E27 -> 2700 | N27: BP313052P | O27: =O8*180% -> 9606.6 | P27: m | Q27: =T12 -> 4.0595 | R27: =O27*Q27 -> 38997.993 | S27: =O27/23 -> 417.67826 | T27: =S27*$U$24 -> 22972.304 | Y27: BP313052P | Z27: =Z8*180% -> 9606.6 | AA27: m | AB27: =AE12 -> 4.2205 | AC27: =Z27*AB27 -> 40544.655 | AD27: =Z27/23 -> 417.67826 | AE27: =AD27*$U$24 -> 22972.304 | AJ27: BP313052P | AK27: =AK8*180% -> 9606.6 | AL27: m | AM27: =AP12 -> 3.864 | AN27: =AK27*AM27 -> 37119.902 | AO27: =AK27/23 -> 417.67826 | AP27: =AO27*$U$24 -> 22972.304
B28: Fixings | C28: =C7*66% -> 3522.42 | D28: ea | E28: 3 | F28: =C28*E28 -> 10567.26 | G28: =C28/13 -> 270.95538 | H28: =G28*$I$23 -> 14902.546 | N28: ACM7 Clips | O28: =SUM(O12/2)/0.9 -> 680 | P28: ea | Q28: =T14 -> 2.2655 | R28: =O28*Q28 -> 1540.54 | S28: =O28/30 -> 22.666667 | T28: =S28*$U$24 -> 1246.6667 | Y28: ACM7 Clips | Z28: =SUM(Z12/2)/0.9 -> 680 | AA28: ea | AB28: =AE14 -> 2.2655 | AC28: =Z28*AB28 -> 1540.54 | AD28: =Z28/30 -> 22.666667 | AE28: =AD28*$U$24 -> 1246.6667 | AJ28: ACM7 Clips | AK28: =SUM(AK12/2)/0.9 -> 680 | AL28: ea | AM28: =AP14 -> 2.2655 | AN28: =AK28*AM28 -> 1540.54 | AO28: =AK28/30 -> 22.666667 | AP28: =AO28*$U$24 -> 1246.6667
B29: Grid Only | C29: =F29+H29 -> 119181.76 | F29: =SUM(F23:F28) -> 61752.259 | H29: =SUM(H24:H28) -> 57429.503 | N29: Wire | O29: =ROUND(O8/200, 0) -> 27 | P29: ea | Q29: 115 | R29: =O29*Q29 -> 3105 | U29: =T29*$I$21 -> 0 | Y29: Wire | Z29: =ROUND(Z8/200, 0) -> 27 | AA29: ea | AB29: 115 | AC29: =Z29*AB29 -> 3105 | AF29: =AE29*$I$21 -> 0 | AJ29: Wire | AK29: =ROUND(AK8/200, 0) -> 27 | AL29: ea | AM29: 115 | AN29: =AK29*AM29 -> 3105 | AQ29: =AP29*$I$21 -> 0
C30: =C29/C7 -> 22.331228 | D30: M2 | E30: mat | F30: =F29/C7 -> 11.570594 | G30: lab | H30: =H29/C7 -> 10.760634 | I30: =H30/I23 -> 0.19564789 | N30: Fixings | O30: =O8*66% -> 3522.42 | P30: ea | Q30: 1.5 | R30: =O30*Q30 -> 5283.63 | S30: =O30/13 -> 270.95538 | T30: =S30*$U$24 -> 14902.546 | Y30: Fixings | Z30: =Z8*66% -> 3522.42 | AA30: ea | AB30: 1.5 | AC30: =Z30*AB30 -> 5283.63 | AD30: =Z30/13 -> 270.95538 | AE30: =AD30*$U$24 -> 14902.546 | AJ30: Fixings | AK30: =AK8*66% -> 3522.42 | AL30: ea | AM30: 1.5 | AN30: =AK30*AM30 -> 5283.63 | AO30: =AK30/13 -> 270.95538 | AP30: =AO30*$U$24 -> 14902.546
N31: Grid Only | O31: =R31+T31 -> 119521.39 | R31: =SUM(R24:R30) -> 64564.039 | T31: =SUM(T25:T30) -> 54957.356 | Y31: Grid Only | Z31: =AC31+AE31 -> 121706.04 | AC31: =SUM(AC24:AC30) -> 66748.683 | AE31: =SUM(AE25:AE30) -> 54957.356 | AJ31: Grid Only | AK31: =AN31+AP31 -> 118237.51 | AN31: =SUM(AN24:AN30) -> 63280.149 | AP31: =SUM(AP25:AP30) -> 54957.356
B32: Ceiling Tiles | C32: =C7/0.72 -> 7412.5 | D32: ea | E32: =C13 -> 22.636897 | F32: =C32*E32 -> 167796 | G32: =C7/10 -> 533.7 | H32: =G32*$I$23 -> 29353.5 | O32: =O31/O8 -> 22.394865 | P32: M2 | Q32: mat | R32: =R31/O8 -> 12.09744 | S32: lab | T32: =T31/O8 -> 10.297425 | U32: =T32/U24 -> 0.18722591 | Z32: =Z31/Z8 -> 22.804205 | AA32: M2 | AB32: mat | AC32: =AC31/Z8 -> 12.50678 | AD32: lab | AE32: =AE31/Z8 -> 10.297425 | AF32: =AE32/AF24 -> 0.18722591 | AK32: =AK31/AK8 -> 22.154301 | AL32: M2 | AM32: mat | AN32: =AN31/AK8 -> 11.856876 | AO32: lab | AP32: =AP31/AK8 -> 10.297425 | AQ32: =AP32/AQ24 -> 0.18722591
B33: Tiles Only | C33: =F32+H32 -> 197149.5
C34: =C33/C7 -> 36.940135 | D34: M2 | E34: mat | F34: =F32/C7 -> 31.440135 | G34: lab | H34: =H32/C7 -> 5.5 | I34: m2 | J34: =H34/I23 -> 0.1 | N34: Ceiling Tiles | O34: =O8/0.9 -> 5930 | P34: ea | Q34: =O14 -> 31.689713 | R34: =O34*Q34 -> 187920 | S34: =O8/10 -> 533.7 | T34: =S34*$U$24 -> 29353.5 | Y34: Ceiling Tiles | Z34: =Z8/0.9 -> 5930 | AA34: ea | AB34: =Z14 -> 34.360877 | AC34: =Z34*AB34 -> 203760 | AD34: =Z8/10 -> 533.7 | AE34: =AD34*$U$24 -> 29353.5 | AJ34: Ceiling Tiles | AK34: =AK8/0.9 -> 5930 | AL34: ea | AM34: =AK14 -> 32.693929 | AN34: =AK34*AM34 -> 193875 | AO34: =AK8/10 -> 533.7 | AP34: =AO34*$U$24 -> 29353.5
G35: =SUM(G24:G32) -> 1577.8728 | H35: tot hours | N35: Tiles Only | O35: =R34+T34 -> 217273.5 | Y35: Tiles Only | Z35: =AC34+AE34 -> 233113.5 | AJ35: Tiles Only | AK35: =AN34+AP34 -> 223228.5
B36: Cost | C36: =C30+C34 -> 59.271363 | D36: M2 | O36: =O35/O8 -> 40.710793 | P36: M2 | Q36: mat | R36: =R34/O8 -> 35.210793 | S36: lab | T36: =T34/O8 -> 5.5 | U36: m2 | V36: =T36/U24 -> 0.1 | Z36: =Z35/Z8 -> 43.678752 | AA36: M2 | AB36: mat | AC36: =AC34/Z8 -> 38.178752 | AD36: lab | AE36: =AE34/Z8 -> 5.5 | AF36: m2 | AG36: =AE36/AF24 -> 0.1 | AK36: =AK35/AK8 -> 41.826588 | AL36: M2 | AM36: mat | AN36: =AN34/AK8 -> 36.326588 | AO36: lab | AP36: =AP34/AK8 -> 5.5 | AQ36: m2 | AR36: =AP36/AQ24 -> 0.1
E37: mat | S37: =SUM(S25:S34) -> 1532.9247 | T37: tot hours | AD37: =SUM(AD25:AD34) -> 1532.9247 | AE37: tot hours | AO37: =SUM(AO25:AO34) -> 1532.9247 | AP37: tot hours
E38: =F32+F29 -> 229548.26 | H38: Actual cost of ceiling | N38: Cost | O38: =O32+O36 -> 63.105658 | P38: M2 | Y38: Cost | Z38: =Z32+Z36 -> 66.482957 | AA38: M2 | AJ38: Cost | AK38: =AK32+AK36 -> 63.980889 | AL38: M2
E39: =F34+F30 -> 43.010729 | F39: m2 | H39: =E39 -> 43.010729 | I39: m2 | Q39: mat | AB39: mat | AM39: mat
E40: lab | Q40: =R34+R31 -> 252484.04 | T40: Actual cost of ceiling | AB40: =AC34+AC31 -> 270508.68 | AE40: Actual cost of ceiling | AM40: =AN34+AN31 -> 257155.15 | AP40: Actual cost of ceiling
E41: =H32+H29 -> 86783.003 | H41: Contract rate | O41: =Q41/Q46 -> 0.74966706 | Q41: =R36+R32 -> 47.308233 | R41: m2 | T41: =Q41 -> 47.308233 | U41: m2 | Z41: =AB41/AB46 -> 0.76238384 | AB41: =AC36+AC32 -> 50.685532 | AC41: m2 | AE41: =AB41 -> 50.685532 | AF41: m2 | AK41: =AM41/AM46 -> 0.75309151 | AM41: =AN36+AN32 -> 48.183464 | AN41: m2 | AP41: =AM41 -> 48.183464 | AQ41: m2
E42: =E41/C7 -> 16.260634 | F42: m2 | H42: =E42 -> 16.260634 | Q42: lab | AB42: lab | AM42: lab
D43: Actual cost | Q43: =T34+T31 -> 84310.856 | T43: Contract rate | AB43: =AE34+AE31 -> 84310.856 | AE43: Contract rate | AM43: =AP34+AP31 -> 84310.856 | AP43: Contract rate
...

Sheet Sheet1
E7: ***POST APRIL***
B8: Armstrong
B10: Job Name
B11: total sqm | C11: 4001 | D11: m2 | F11: Standard grid | H11: 5% Freight
B12: Cost Plus Margin | F12: Nett cost | H12: 10% waste
B13: admin | F13: Wall angle | G13: 2.2 | H13: =G13*1.15 -> 2.53
B14: hourly rate | C14: 50 | F14: Mains | G14: 3 | H14: =G14*1.15 -> 3.45
B15: wall trim | C15: 1698 | D15: m | F15: 1500 Nogs | G15: 3.36 | H15: =G15*1.15 -> 3.864
B16: tile type | C16: Eurocoustic Tonga white
B17: tile price | C17: =K23 -> 32.725044 | D17: per tile | F17: Berc Clips | G17: 1.97 | H17: =G17*1.15 -> 2.2655
B18: Module | C18: 1500 x 600
I19: $28.28 per tile plus 5% Freight $29.69
I20: tiles plus 10% wastage
B21: Total Cost | C21: =C11*C41 -> 257933.41 | I21: 4891 | J21: 490 boxes
B22: Total Revenue | C22: =C21*(1+C12) -> 257933.41 | D22: Price | I22: 490 boxes @ $296.90 | K22: 145481
B23: Profit | C23: =C22-C21 -> 0 | K23: =K22/C37 -> 32.725044
B25: Standard grid
B26: Peakform | E26: Waste 10% on product include in cost
B27: Adminstration | E27: COST | F27: =SUM(C13) -> 0 | G27: HOURS | H27: COST | I27: 50
B28: BPT1932H | C28: =C15 -> 1698 | D28: m | E28: =H13 -> 2.53 | F28: =C28*E28 -> 4295.94 | G28: =C28/10 -> 169.8 | H28: =G28*$I$27 -> 8490 | I28: =H28/I27 -> 169.8 | J28: =I28/C15 -> 0.1 | K28: =F28/C28 -> 2.53
B29: BP734042P | C29: =(C11/1.5)*1.07 -> 2854.0467 | D29: m | E29: =H14 -> 3.45 | F29: =C29*E29 -> 9846.461 | G29: =C29/23 -> 124.08899 | H29: =G29*$I$27 -> 6204.4493
B30: BP313052P | C30: =C11*180% -> 7201.8 | D30: m | E30: =H15 -> 3.864 | F30: =C30*E30 -> 27827.755 | G30: =C30/23 -> 313.12174 | H30: =G30*$I$27 -> 15656.087
B31: ACM7 Clips | C31: =SUM(C15/2)/0.9 -> 943.33333 | D31: ea | E31: =H17 -> 2.2655 | F31: =C31*E31 -> 2137.1217 | G31: =C31/30 -> 31.444444 | H31: =G31*$I$27 -> 1572.2222
B32: Wire | C32: =ROUND(C11/200, 0) -> 20 | D32: ea | E32: 115 | F32: =C32*E32 -> 2300 | I32: =H32*$I$21 -> 0
B33: Fixings | C33: =C11*66% -> 2640.66 | D33: ea | E33: 1.5 | F33: =C33*E33 -> 3960.99 | G33: =C33/13 -> 203.12769 | H33: =G33*$I$27 -> 10156.385
B34: Grid Only | C34: =F34+H34 -> 92447.411 | F34: =SUM(F27:F33) -> 50368.268 | H34: =SUM(H28:H33) -> 42079.143
C35: =C34/C11 -> 23.106076 | D35: M2 | E35: mat | F35: =F34/C11 -> 12.58892 | G35: lab | H35: =H34/C11 -> 10.517156 | I35: =H35/I27 -> 0.21034313 | J35: =I35-J28 -> 0.11034313
B37: Ceiling Tiles | C37: =C11/0.9 -> 4445.5556 | D37: ea | E37: =C17 -> 32.725044 | F37: =C37*E37 -> 145481 | G37: =C11/10 -> 400.1 | H37: =G37*$I$27 -> 20005
B38: Tiles Only | C38: =F37+H37 -> 165486
C39: =C38/C11 -> 41.36116 | D39: M2 | E39: mat | F39: =F37/C11 -> 36.36116 | G39: lab | H39: =H37/C11 -> 5 | I39: m2 | J39: =H39/I27 -> 0.1
G40: =SUM(G28:G37) -> 1241.6829 | H40: tot hours
B41: Cost | C41: =C35+C39 -> 64.467236 | D41: M2
E42: mat
E43: =F37+F34 -> 195849.27 | H43: Actual cost of ceiling
C44: =E44/E49 -> 0.75930166 | E44: =F39+F35 -> 48.950079 | F44: m2 | H44: =E44 -> 48.950079 | I44: m2
E45: lab
E46: =H37+H34 -> 62084.143 | H46: Contract rate
C47: =E47/E49 -> 0.24069834 | E47: =H39+H35 -> 15.517156 | F47: m2 | H47: 6.5
D48: Actual cost
E49: =E44+E47 -> 64.467236
...

Sheet Steel Stud Partitions_25_8
B1: =Summary!B1 -> Ceilings Unlimited
B2: =Summary!B2 -> 2 Devonport Road
B3: =Summary!B3 -> Tauranga
B6: 45853
B9: Steel Stud Partitions
H11: 50
A12: Item | B12: Description | C12: Qty | D12: Unit | E12: Constant | F12: Constant X Unit = Total HRS | G12: $ Lab per Unit | H12: Total Labour | I12: Materials per Unit | J12: Total Materials | K12: Total Labour & Materials | L12: Total Labour & Materials Per Unit | M12: Total | N12: % Complete | O12: Claim | U12: =SUM(C16,C22,C29,C35,C42,C47,C55,C60,C68,C73,C81,C86,C94,C99,C107) -> 1912
B15: Basement:
B16: (WA52) 92mm x 0.55 Whisper Wall Stud (3.4m) | C16: 98 | D16: m2 | E16: =$Y$20 -> 0.4 | F16: =C16*E16 -> 39.2 | G16: =$H$11*E16 -> 20 | H16: =F16*$H$11 -> 1960 | I16: 15.19 | J16: =C16*I16 -> 1488.62 | K16: =SUM(H16,J16) -> 3448.62 | L16: =K16/C16 -> 35.19 | M16: =C16*L16 -> 3448.62 | N16: 0 | O16: =M16*N16 -> 0 | T16: 29/lm
B17: EV Stud to Corners/Wall Ends | C17: 133 | D17: m | E17: 0.07 | F17: =C17*E17 -> 9.31 | G17: =$H$11*E17 -> 3.5 | H17: =F17*$H$11 -> 465.5 | I17: 7 | J17: =C17*I17 -> 931 | K17: =SUM(H17,J17) -> 1396.5 | L17: =K17/C17 -> 10.5 | M17: =C17*L17 -> 1396.5 | N17: 0 | O17: =M17*N17 -> 0
B18: Infill to Comflor take head track | C18: 29 | D18: m | E18: 0.25 | F18: =C18*E18 -> 7.25 | G18: =$H$11*E18 -> 12.5 | H18: =F18*$H$11 -> 362.5 | I18: 15 | J18: =C18*I18 -> 435 | K18: =SUM(H18,J18) -> 797.5 | L18: =K18/C18 -> 27.5 | M18: =C18*L18 -> 797.5 | N18: 0 | O18: =M18*N18 -> 0 | V18: =SUM(F17,F16) -> 48.51
B19: Gib Packing to Head | C19: 29 | D19: m | E19: 0.15 | F19: =C19*E19 -> 4.35 | G19: =$H$11*E19 -> 7.5 | H19: =F19*$H$11 -> 217.5 | I19: 6 | J19: =C19*I19 -> 174 | K19: =SUM(H19,J19) -> 391.5 | L19: =K19/C19 -> 13.5 | M19: =C19*L19 -> 391.5 | N19: 0 | O19: =M19*N19 -> 0 | V19: =V18/C16 -> 0.495
P20: =SUM(M16:M19) -> 6034.12 | Q20: =P20*SUM($L$115:$L$119) -> 573.2414 | Y20: 0.4
B21: Ground: | P21: =P20/$M$112 -> 0.065341427 | Q21: =P21*$M$123 -> 154.95866 | R21: =SUM(P20,Q20,Q21) -> 6762.3201 | S21: =R21*1.08 -> 7303.3057
B22: (WA06) 64mm x 0.55 Steel Stud (4.2m) | C22: 95 | D22: m2 | E22: =$Y$20 -> 0.4 | F22: =C22*E22 -> 38 | G22: =$H$11*E22 -> 20 | H22: =F22*$H$11 -> 1900 | I22: 10.77 | J22: =C22*I22 -> 1023.15 | K22: =SUM(H22,J22) -> 2923.15 | L22: =K22/C22 -> 30.77 | M22: =C22*L22 -> 2923.15 | N22: 0 | O22: =M22*N22 -> 0 | T22: 23/lm | V22: =SUM(F22:F23) -> 41.55
B23: EV Stud to Corners/Wall Ends | C23: 71 | D23: m | E23: 0.05 | F23: =C23*E23 -> 3.55 | G23: =$H$11*E23 -> 2.5 | H23: =F23*$H$11 -> 177.5 | I23: 2.7 | J23: =C23*I23 -> 191.7 | K23: =SUM(H23,J23) -> 369.2 | L23: =K23/C23 -> 5.2 | M23: =C23*L23 -> 369.2 | N23: 0 | O23: =M23*N23 -> 0 | V23: =V22/C22 -> 0.43736842
B24: Infill to Comflor take head track | C24: 23 | D24: m | E24: 0.25 | F24: =C24*E24 -> 5.75 | G24: =$H$11*E24 -> 12.5 | H24: =F24*$H$11 -> 287.5 | I24: 15 | J24: =C24*I24 -> 345 | K24: =SUM(H24,J24) -> 632.5 | L24: =K24/C24 -> 27.5 | M24: =C24*L24 -> 632.5 | N24: 0 | O24: =M24*N24 -> 0
B25: Gib Packing to Head | C25: 23 | D25: m | E25: 0.15 | F25: =C25*E25 -> 3.45 | G25: =$H$11*E25 -> 7.5 | H25: =F25*$H$11 -> 172.5 | I25: 6 | J25: =C25*I25 -> 138 | K25: =SUM(H25,J25) -> 310.5 | L25: =K25/C25 -> 13.5 | M25: =C25*L25 -> 310.5 | N25: 0 | O25: =M25*N25 -> 0
P26: =SUM(M22:M25) -> 4235.35 | Q26: =P26*SUM($L$115:$L$119) -> 402.35825
P27: =P26/$M$112 -> 0.04586316 | Q27: =P27*$M$123 -> 108.76552 | R27: =SUM(P26,Q26,Q27) -> 4746.4738 | S27: =R27*1.08 -> 5126.1917
B28: Level 1:
B29: (WA06) 64mm x 0.55 Steel Stud (4.2m) | C29: 185 | D29: m2 | E29: =$Y$20 -> 0.4 | F29: =C29*E29 -> 74 | G29: =$H$11*E29 -> 20 | H29: =F29*$H$11 -> 3700 | I29: 10.77 | J29: =C29*I29 -> 1992.45 | K29: =SUM(H29,J29) -> 5692.45 | L29: =K29/C29 -> 30.77 | M29: =C29*L29 -> 5692.45 | N29: 0 | O29: =M29*N29 -> 0 | T29: 44/lm | V29: =SUM(F29:F30) -> 84.1
B30: EV Stud to Corners/Wall Ends | C30: 202 | D30: m | E30: 0.05 | F30: =C30*E30 -> 10.1 | G30: =$H$11*E30 -> 2.5 | H30: =F30*$H$11 -> 505 | I30: 2.7 | J30: =C30*I30 -> 545.4 | K30: =SUM(H30,J30) -> 1050.4 | L30: =K30/C30 -> 5.2 | M30: =C30*L30 -> 1050.4 | N30: 0 | O30: =M30*N30 -> 0 | V30: =V29/C29 -> 0.45459459
B31: Infill to Comflor take head track | C31: 44 | D31: m | E31: 0.25 | F31: =C31*E31 -> 11 | G31: =$H$11*E31 -> 12.5 | H31: =F31*$H$11 -> 550 | I31: 15 | J31: =C31*I31 -> 660 | K31: =SUM(H31,J31) -> 1210 | L31: =K31/C31 -> 27.5 | M31: =C31*L31 -> 1210 | N31: 0 | O31: =M31*N31 -> 0
B32: Gib Packing to Head | C32: 44 | D32: m | E32: 0.15 | F32: =C32*E32 -> 6.6 | G32: =$H$11*E32 -> 7.5 | H32: =F32*$H$11 -> 330 | I32: 6 | J32: =C32*I32 -> 264 | K32: =SUM(H32,J32) -> 594 | L32: =K32/C32 -> 13.5 | M32: =C32*L32 -> 594 | N32: 0 | O32: =M32*N32 -> 0
B35: (WA52) 92mm x 0.55 Whisper Wall Stud (4.2m) | C35: 64 | D35: m2 | E35: =$Y$20 -> 0.4 | F35: =C35*E35 -> 25.6 | G35: =$H$11*E35 -> 20 | H35: =F35*$H$11 -> 1280 | I35: 14.55 | J35: =C35*I35 -> 931.2 | K35: =SUM(H35,J35) -> 2211.2 | L35: =K35/C35 -> 34.55 | M35: =C35*L35 -> 2211.2 | N35: 0 | O35: =M35*N35 -> 0 | T35: 15/lm | V35: =SUM(F35:F36) -> 30.01
B36: EV Stud to Corners/Wall Ends | C36: 63 | D36: m | E36: 0.07 | F36: =C36*E36 -> 4.41 | G36: =$H$11*E36 -> 3.5 | H36: =F36*$H$11 -> 220.5 | I36: 7 | J36: =C36*I36 -> 441 | K36: =SUM(H36,J36) -> 661.5 | L36: =K36/C36 -> 10.5 | M36: =C36*L36 -> 661.5 | N36: 0 | O36: =M36*N36 -> 0 | V36: =V35/C35 -> 0.46890625
B37: Infill to Comflor take head track | C37: 15 | D37: m | E37: 0.25 | F37: =C37*E37 -> 3.75 | G37: =$H$11*E37 -> 12.5 | H37: =F37*$H$11 -> 187.5 | I37: 15 | J37: =C37*I37 -> 225 | K37: =SUM(H37,J37) -> 412.5 | L37: =K37/C37 -> 27.5 | M37: =C37*L37 -> 412.5 | N37: 0 | O37: =M37*N37 -> 0
B38: Gib Packing to Head | C38: 15 | D38: m | E38: 0.15 | F38: =C38*E38 -> 2.25 | G38: =$H$11*E38 -> 7.5 | H38: =F38*$H$11 -> 112.5 | I38: 6 | J38: =C38*I38 -> 90 | K38: =SUM(H38,J38) -> 202.5 | L38: =K38/C38 -> 13.5 | M38: =C38*L38 -> 202.5 | N38: 0 | O38: =M38*N38 -> 0
P39: =SUM(M29:M38) -> 12034.55 | Q39: =P39*SUM($L$115:$L$119) -> 1143.2822
P40: =P39/$M$112 -> 0.13031804 | Q40: =P40*$M$123 -> 309.05215 | R40: =SUM(P39,Q39,Q40) -> 13486.884 | S40: =R40*1.08 -> 14565.835
B41: Level 2:
B42: (WA06) 64mm x 0.55 Steel Stud (4.2m) | C42: 232 | D42: m2 | E42: =$Y$20 -> 0.4 | F42: =C42*E42 -> 92.8 | G42: =$H$11*E42 -> 20 | H42: =F42*$H$11 -> 4640 | I42: 10.77 | J42: =C42*I42 -> 2498.64 | K42: =SUM(H42,J42) -> 7138.64 | L42: =K42/C42 -> 30.77 | M42: =C42*L42 -> 7138.64 | N42: 0 | O42: =M42*N42 -> 0 | T42: 55/lm | V42: =SUM(F42:F43) -> 104.75
B43: EV Stud to Corners/Wall Ends | C43: 239 | D43: m | E43: 0.05 | F43: =C43*E43 -> 11.95 | G43: =$H$11*E43 -> 2.5 | H43: =F43*$H$11 -> 597.5 | I43: 2.7 | J43: =C43*I43 -> 645.3 | K43: =SUM(H43,J43) -> 1242.8 | L43: =K43/C43 -> 5.2 | M43: =C43*L43 -> 1242.8 | N43: 0 | O43: =M43*N43 -> 0 | V43: =V42/C42 -> 0.45150862
B44: Infill to Comflor take head track | C44: 55 | D44: m | E44: 0.25 | F44: =C44*E44 -> 13.75 | G44: =$H$11*E44 -> 12.5 | H44: =F44*$H$11 -> 687.5 | I44: 15 | J44: =C44*I44 -> 825 | K44: =SUM(H44,J44) -> 1512.5 | L44: =K44/C44 -> 27.5 | M44: =C44*L44 -> 1512.5 | N44: 0 | O44: =M44*N44 -> 0
B45: Gib Packing to Head | C45: 55 | D45: m | E45: 0.15 | F45: =C45*E45 -> 8.25 | G45: =$H$11*E45 -> 7.5 | H45: =F45*$H$11 -> 412.5 | I45: 6 | J45: =C45*I45 -> 330 | K45: =SUM(H45,J45) -> 742.5 | L45: =K45/C45 -> 13.5 | M45: =C45*L45 -> 742.5 | N45: 0 | O45: =M45*N45 -> 0
B47: (WA52) 92mm x 0.55 Whisper Wall Stud (4.2m) | C47: 51 | D47: m2 | E47: =$Y$20 -> 0.4 | F47: =C47*E47 -> 20.4 | G47: =$H$11*E47 -> 20 | H47: =F47*$H$11 -> 1020 | I47: 14.67 | J47: =C47*I47 -> 748.17 | K47: =SUM(H47,J47) -> 1768.17 | L47: =K47/C47 -> 34.67 | M47: =C47*L47 -> 1768.17 | N47: 0.75 | O47: =M47*N47 -> 1326.1275 | T47: 12/lm | V47: =SUM(F47:F48) -> 25.37
B48: EV Stud to Corners/Wall Ends | C48: 71 | D48: m | E48: 0.07 | F48: =C48*E48 -> 4.97 | G48: =$H$11*E48 -> 3.5 | H48: =F48*$H$11 -> 248.5 | I48: 7 | J48: =C48*I48 -> 497 | K48: =SUM(H48,J48) -> 745.5 | L48: =K48/C48 -> 10.5 | M48: =C48*L48 -> 745.5 | N48: 0.75 | O48: =M48*N48 -> 559.125 | V48: =V47/C47 -> 0.49745098
B49: Infill to Comflor take head track | C49: 12 | D49: m | E49: 0.25 | F49: =C49*E49 -> 3 | G49: =$H$11*E49 -> 12.5 | H49: =F49*$H$11 -> 150 | I49: 15 | J49: =C49*I49 -> 180 | K49: =SUM(H49,J49) -> 330 | L49: =K49/C49 -> 27.5 | M49: =C49*L49 -> 330 | N49: 0 | O49: =M49*N49 -> 0
B50: Gib Packing to Head | C50: 12 | D50: m | E50: 0.15 | F50: =C50*E50 -> 1.8 | G50: =$H$11*E50 -> 7.5 | H50: =F50*$H$11 -> 90 | I50: 6 | J50: =C50*I50 -> 72 | K50: =SUM(H50,J50) -> 162 | L50: =K50/C50 -> 13.5 | M50: =C50*L50 -> 162 | N50: 0 | O50: =M50*N50 -> 0 | P50: =SUM(O42:O50) -> 1885.2525 | Q50: =P50/P51 -> 0.13819362
...

Sheet Workings_Partitions
D8: 92mm QS steel studs @ | E8: 0.6 | F8: Stud spacing | G8: With DH | M8: WA52 | Q8: 92mm QS steel studs @ | R8: 0.6 | S8: Stud spacing | T8: With DH | Z8: WA52
D10: Material | F10: Length of wall | G10: Height of wall | H10: Total stud LM | I10: Total track LM | J10: M2 of wall | Q10: Material | S10: Length of wall | T10: Height of wall | U10: Total stud LM | V10: Total track LM | W10: M2 of wall
E11: $/m | F11: 29 | G11: 3.4 | H11: =SUM(F20*G11) -> 167.73333 | I11: =F11*1 -> 29 | J11: =F11*G11 -> 98.6 | R11: $/m | S11: 12 | T11: 4.2 | U11: =SUM(S20*T11) -> 88.2 | V11: =S11*1 -> 12 | W11: =S11*T11 -> 50.4
C12: Stud | D12: 92 QS .55 bmt | E12: 7.4 | P12: Stud | Q12: 92 QS .55 bmt | R12: 5.9
D13: Nog | E13: =H14/H11 -> 3.7794515 | F13: 10.93 | G13: m | H13: =SUM(F13*F11) -> 316.97 | Q13: Nog | R13: =U14/U11 -> 0.80136054 | S13: 5.89 | T13: m | U13: =SUM(S13*S11) -> 70.68
F14: Number of nogs | G14: 2 | H14: =G14*H13 -> 633.94 | S14: Number of nogs | T14: 1 | U14: =T14*U13 -> 70.68
D16: Unload | E16: 0.09 | Q16: Unload | R16: 0.09
D17: Fixings | Q17: Fixings
D18: say 4 each stud | Q18: say 4 each stud
D19: L of wl ÷ spacings = ttl studs | F19: =SUM(F11/E8) -> 48.333333 | Q19: L of wl ÷ spacings = ttl studs | S19: =SUM(S11/R8) -> 20
D20: add 1 for end of wall | F20: =F19+1 -> 49.333333 | G20: total studs in wall | Q20: add 1 for end of wall | S20: =S19+1 -> 21 | T20: total studs in wall
D21: Studs x 4 screws per stud = ttl screws | F21: =SUM(F20*4) -> 197.33333 | G21: total screws | H21: 0.015 | Q21: Studs x 4 screws per stud = ttl screws | S21: =SUM(S20*4) -> 84 | T21: total screws | U21: 0.015
D22: Screws @ $15.00/1000 = .015 | E22: =SUM(F21*H21)/H11 -> 0.017647059 | F22: Cost of fixings per LM | Q22: Screws @ $15.00/1000 = .015 | R22: =SUM(S21*U21)/U11 -> 0.014285714 | S22: Cost of fixings per LM
E24: =SUM(E12:E23) -> 11.287099 | R24: =SUM(R12:R23) -> 6.8056463
D25: waste 5% | E25: =E24*5% -> 0.56435493 | Q25: waste 5% | R25: =R24*5% -> 0.34028231
E26: =SUM(E24:E25) -> 11.851453 | R26: =SUM(R24:R25) -> 7.1459286
C27: Stud | D27: Labour per m as per rates | F27: Lab rate | P27: Stud | Q27: Labour per m as per rates | S27: Lab rate
D28: m/hr | F28: 55 | Q28: m/hr | S28: 55
D29: 20 | E29: =F28/D29 -> 2.75 | Q29: 15 | R29: =S28/Q29 -> 3.6666667
E32: =SUM(E26:E29) -> 14.601453 | I32: Labour cost per m | L32: per m2 | R32: =SUM(R26:R29) -> 10.812595 | V32: Labour cost per m | Y32: per m2
D33: Plant | I33: =E35-I35 -> 3.5745727 | K33: =H11*I33 -> 599.57499 | L33: =K33/J11 -> 6.0808823 | Q33: Plant | V33: =R35-V35 -> 4.3017964 | X33: =U11*V33 -> 379.41845 | Y33: =X33/W11 -> 7.5281437
D34: 0.05 | E34: =E32*5% -> 0.73007267 | I34: Material cost per m | Q34: 0.05 | R34: =R32*5% -> 0.54062976 | V34: Material cost per m
E35: =SUM(E32:E34) -> 15.331526 | F35: per m | I35: =SUM(E12+E13+E22)*1.05 -> 11.756953 | K35: =H11*I35 -> 1972.033 | L35: =K35/J11 -> 20.000335 | R35: =SUM(R32:R34) -> 11.353225 | S35: per m | V35: =SUM(R12+R13+R22)*1.05 -> 7.0514286 | X35: =U11*V35 -> 621.936 | Y35: =X35/W11 -> 12.34
D36: Total cost of stud job is | F36: =E35*H11 -> 2571.608 | Q36: Total cost of stud job is | S36: =R35*U11 -> 1001.3544
F37: To get the medium of the two | S37: To get the medium of the two
C38: Track | D38: 92 .75 bmt x 1 , DH x 1 | E38: =I39 -> 3.815 | F38: Top | G38: Bot | I38: Avge | P38: Track | Q38: 92 .75 bmt x 1 , DH x 1 | R38: =V39 -> 4.435 | S38: Top | T38: Bot | V38: Avge
D39: DPC | E39: 0.31 | F39: 4.78 | G39: 2.85 | H39: =SUM(F39:G39) -> 7.63 | I39: =H39/2 -> 3.815 | Q39: DPC | R39: 0.31 | S39: 4.78 | T39: 4.09 | U39: =SUM(S39:T39) -> 8.87 | V39: =U39/2 -> 4.435
D40: Unload | E40: 0.09 | Q40: Unload | R40: 0.09
D42: Fixings for track | Q42: Fixings for track
D43: Spaced @ 0.6 1.7 @ 2.50 each | F43: =F11/E8 -> 48.333333 | Q43: Spaced @ 0.6 1.7 @ 2.50 each | S43: =S11/R8 -> 20
D44: add extra for ends | F44: =F43+2 -> 50.333333 | G44: total fixings | H44: 2.5 | Q44: add extra for ends | S44: =S43+2 -> 22 | T44: total fixings | U44: 2.5
E45: =SUM(F44*H44)/I11 -> 4.3390805 | F45: Cost of fixings per LM | R45: =SUM(S44*U44)/V11 -> 4.5833333 | S45: Cost of fixings per LM
E47: =SUM(E38:E45) -> 8.5540805 | R47: =SUM(R38:R45) -> 9.4183333
D48: waste 5% | E48: =E47*5% -> 0.42770402 | Q48: waste 5% | R48: =R47*5% -> 0.47091667
E49: =SUM(E47:E48) -> 8.9817845 | R49: =SUM(R47:R48) -> 9.88925
C50: Track | D50: Labour per m as per rates | F50: Lab rate | P50: Track | Q50: Labour per m as per rates | S50: Lab rate
D51: m/hr | F51: 55 | Q51: m/hr | S51: 55
D52: 4 | E52: =F51/D52 -> 13.75 | Q52: 4 | R52: =S51/Q52 -> 13.75
E53: =SUM(E49:E52) -> 22.731784 | I53: Labour cost per m | L53: per m2 | R53: =SUM(R49:R52) -> 23.63925 | V53: Labour cost per m | Y53: per m2
D54: Plant | I54: =E56-I56 -> 14.981089 | K54: =I11*I54 -> 434.45159 | L54: =K54/J11 -> 4.4062027 | Q54: Plant | V54: =R56-V56 -> 15.026463 | X54: =V11*V54 -> 180.31755 | Y54: =X54/W11 -> 3.5777292
...

Sheet Gib Linings_25_8
B1: =Summary!#REF! -> #REF!
B2: =Summary!#REF! -> #REF!
B3: =Summary!#REF! -> #REF!
B6: 45853
B9: Gib Wall and Ceiling Linings
H11: 40
A12: Item | B12: Description | C12: Qty | D12: Unit | E12: Constant | F12: Constant X Unit = Total HRS | G12: $ Lab per Unit | H12: Total Labour | I12: Materials per Unit | J12: Total Materials | K12: Total Labour & Materials | L12: Total Labour & Materials Per Unit | M12: Total | N12: % Complete | O12: Claim
B15: Basement: | T15: =SUM(C17,C18,C20) -> 107
B16: Ceiling Linings:
B17: (CS01) 13mm Gib Standard | C17: 65 | D17: m2 | E17: 0.2 | F17: =C17*E17 -> 13 | G17: =$H$11*E17 -> 8 | H17: =F17*$H$11 -> 520 | I17: 13.51 | J17: =C17*I17 -> 878.15 | K17: =SUM(H17,J17) -> 1398.15 | L17: =K17/C17 -> 21.51 | M17: =C17*L17 -> 1398.15 | N17: 0 | O17: =M17*N17 -> 0
B18: (CS01) 13mm Gib Aqualine | C18: 31 | D18: m2 | E18: 0.2 | F18: =C18*E18 -> 6.2 | G18: =$H$11*E18 -> 8 | H18: =F18*$H$11 -> 248 | I18: 23.99 | J18: =C18*I18 -> 743.69 | K18: =SUM(H18,J18) -> 991.69 | L18: =K18/C18 -> 31.99 | M18: =C18*L18 -> 991.69 | N18: 0 | O18: =M18*N18 -> 0
B20: (WA24) 13mm Gib Standard | C20: 11 | D20: m2 | E20: 0.2 | F20: =C20*E20 -> 2.2 | G20: =$H$11*E20 -> 8 | H20: =F20*$H$11 -> 88 | I20: 13.51 | J20: =C20*I20 -> 148.61 | K20: =SUM(H20,J20) -> 236.61 | L20: =K20/C20 -> 21.51 | M20: =C20*L20 -> 236.61 | N20: 0 | O20: =M20*N20 -> 0 | T20: =SUM(C17:C20) -> 107
B22: Bulkhead Linings:
B23: (CS12) | C23: Nil | T23: =SUM(C23) -> 0
M24: =-T15 -> -107
P25: =SUM(M17:M24) -> 2519.45 | Q25: =P25*SUM($L$585:$L$589) -> 239.34775
P26: =P25/$M$582 -> 0.0064709516 | Q26: =P26*$M$593 -> 54.634908 | R26: =SUM(P25,Q25,Q26) -> 2813.4327 | S26: =R26*1.08 -> 3038.5073
B28: Ground: | T28: =SUM(C30,C31,C33,C33,C36,C36,C39,C42,C44,C46,C48) -> 378
B29: Ceiling Linings:
B30: (CS01) 13mm Gib Standard | C30: 244 | D30: m2 | E30: 0.2 | F30: =C30*E30 -> 48.8 | G30: =$H$11*E30 -> 8 | H30: =F30*$H$11 -> 1952 | I30: 13.51 | J30: =C30*I30 -> 3296.44 | K30: =SUM(H30,J30) -> 5248.44 | L30: =K30/C30 -> 21.51 | M30: =C30*L30 -> 5248.44 | N30: 0 | O30: =M30*N30 -> 0
B31: (CS01) 13mm Gib Aqualine | C31: 23 | D31: m2 | E31: 0.2 | F31: =C31*E31 -> 4.6 | G31: =$H$11*E31 -> 8 | H31: =F31*$H$11 -> 184 | I31: 23.99 | J31: =C31*I31 -> 551.77 | K31: =SUM(H31,J31) -> 735.77 | L31: =K31/C31 -> 31.99 | M31: =C31*L31 -> 735.77 | N31: 0 | O31: =M31*N31 -> 0
B33: (CS10) 16mm Gib Fyreline + 10mm Gib Fyreline | C33: 24 | D33: m2 | E33: 0.6 | F33: =C33*E33 -> 14.4 | G33: =$H$11*E33 -> 24 | H33: =F33*$H$11 -> 576 | I33: 38 | J33: =C33*I33 -> 912 | K33: =SUM(H33,J33) -> 1488 | L33: =K33/C33 -> 62 | M33: =C33*L33 -> 1488 | N33: 0 | O33: =M33*N33 -> 0
B34: Caulking to Above | C34: 21 | D34: m | E34: 0.05 | F34: =C34*E34 -> 1.05 | G34: =$H$11*E34 -> 2 | H34: =F34*$H$11 -> 42 | I34: 2.5 | J34: =C34*I34 -> 52.5 | K34: =SUM(H34,J34) -> 94.5 | L34: =K34/C34 -> 4.5 | M34: =C34*L34 -> 94.5 | N34: 0 | O34: =M34*N34 -> 0
B36: (CS11) 2/13mm Gib Fyreline | C36: 10 | D36: m2 | E36: 0.4 | F36: =C36*E36 -> 4 | G36: =$H$11*E36 -> 16 | H36: =F36*$H$11 -> 160 | I36: 32 | J36: =C36*I36 -> 320 | K36: =SUM(H36,J36) -> 480 | L36: =K36/C36 -> 48 | M36: =C36*L36 -> 480 | N36: 0 | O36: =M36*N36 -> 0
B37: Caulking to Above | C37: 22 | D37: m | E37: 0.05 | F37: =C37*E37 -> 1.1 | G37: =$H$11*E37 -> 2 | H37: =F37*$H$11 -> 44 | I37: 2.5 | J37: =C37*I37 -> 55 | K37: =SUM(H37,J37) -> 99 | L37: =K37/C37 -> 4.5 | M37: =C37*L37 -> 99 | N37: 0 | O37: =M37*N37 -> 0
B39: (CL50) 13mm Gib Standard (Raking to Stair) | C39: 17 | D39: m2 | E39: 0.35 | F39: =C39*E39 -> 5.95 | G39: =$H$11*E39 -> 14 | H39: =F39*$H$11 -> 238 | I39: 13.51 | J39: =C39*I39 -> 229.67 | K39: =SUM(H39,J39) -> 467.67 | L39: =K39/C39 -> 27.51 | M39: =C39*L39 -> 467.67 | N39: 0 | O39: =M39*N39 -> 0 | T39: =SUM(C30,C31,C33,C36,C39) -> 318
B41: Bulkhead Linings:
B42: Bulkhead - 13mm Gib Standard (900) | C42: 15 | D42: m2 | E42: 0.3 | F42: =C42*E42 -> 4.5 | G42: =$H$11*E42 -> 12 | H42: =F42*$H$11 -> 180 | I42: 13.51 | J42: =C42*I42 -> 202.65 | K42: =SUM(H42,J42) -> 382.65 | L42: =K42/C42 -> 25.51 | M42: =C42*L42 -> 382.65 | N42: 0 | O42: =M42*N42 -> 0
B44: Bulkhead - 13mm Gib Standard (1100) | C44: 1 | D44: m2 | E44: 0.3 | F44: =C44*E44 -> 0.3 | G44: =$H$11*E44 -> 12 | H44: =F44*$H$11 -> 12 | I44: 13.51 | J44: =C44*I44 -> 13.51 | K44: =SUM(H44,J44) -> 25.51 | L44: =K44/C44 -> 25.51 | M44: =C44*L44 -> 25.51 | N44: 0 | O44: =M44*N44 -> 0
B46: Bulkhead - 13mmm Gib Standard (1200) | C46: 5 | D46: m2 | E46: 0.3 | F46: =C46*E46 -> 1.5 | G46: =$H$11*E46 -> 12 | H46: =F46*$H$11 -> 60 | I46: 13.51 | J46: =C46*I46 -> 67.55 | K46: =SUM(H46,J46) -> 127.55 | L46: =K46/C46 -> 25.51 | M46: =C46*L46 -> 127.55 | N46: 0 | O46: =M46*N46 -> 0
B48: Bulkhead - 13mm Gib Stanard (1900) | C48: 5 | D48: m2 | E48: 0.3 | F48: =C48*E48 -> 1.5 | G48: =$H$11*E48 -> 12 | H48: =F48*$H$11 -> 60 | I48: 13.51 | J48: =C48*I48 -> 67.55 | K48: =SUM(H48,J48) -> 127.55 | L48: =K48/C48 -> 25.51 | M48: =C48*L48 -> 127.55 | N48: 0 | O48: =M48*N48 -> 0 | T48: =SUM(C42:C48) -> 26
M49: =-T28 -> -378
P50: =SUM(M30:M49) -> 8898.64 | Q50: =P50*SUM($L$585:$L$589) -> 845.3708
P51: =P50/$M$582 -> 0.022855254 | Q51: =P51*$M$593 -> 192.96925 | R51: =SUM(P50,Q50,Q51) -> 9936.98 | S51: =R51*1.08 -> 10731.938
B53: Level 1: | T53: =SUM(C55,C57,C59,C61,C67) -> 356
B54: Ceiling Linings:
B55: (CS01) 13mm Gib Standard | C55: 279 | D55: m2 | E55: 0.2 | F55: =C55*E55 -> 55.8 | G55: =$H$11*E55 -> 8 | H55: =F55*$H$11 -> 2232 | I55: 13.51 | J55: =C55*I55 -> 3769.29 | K55: =SUM(H55,J55) -> 6001.29 | L55: =K55/C55 -> 21.51 | M55: =C55*L55 -> 6001.29 | N55: 0 | O55: =M55*N55 -> 0
B56: EV High Level | C56: 149 | D56: m2 | E56: 0.15 | F56: =C56*E56 -> 22.35 | G56: =$H$11*E56 -> 6 | H56: =F56*$H$11 -> 894 | I56: 0 | J56: =C56*I56 -> 0 | K56: =SUM(H56,J56) -> 894 | L56: =K56/C56 -> 6 | M56: =C56*L56 -> 894 | N56: 0 | O56: =M56*N56 -> 0
B57: (CS01) 13mm Gib Aqualine | C57: 17 | D57: m2 | E57: 0.2 | F57: =C57*E57 -> 3.4 | G57: =$H$11*E57 -> 8 | H57: =F57*$H$11 -> 136 | I57: 23.99 | J57: =C57*I57 -> 407.83 | K57: =SUM(H57,J57) -> 543.83 | L57: =K57/C57 -> 31.99 | M57: =C57*L57 -> 543.83 | N57: 0 | O57: =M57*N57 -> 0
B59: (CL50) 13mm Gib Standard (Raking to Stair) | C59: 34 | D59: m2 | E59: 0.35 | F59: =C59*E59 -> 11.9 | G59: =$H$11*E59 -> 14 | H59: =F59*$H$11 -> 476 | I59: 13.51 | J59: =C59*I59 -> 459.34 | K59: =SUM(H59,J59) -> 935.34 | L59: =K59/C59 -> 27.51 | M59: =C59*L59 -> 935.34 | N59: 0 | O59: =M59*N59 -> 0
...

Sheet Stopping_25_8
B1: =Summary!#REF! -> #REF!
B2: =Summary!#REF! -> #REF!
B3: =Summary!#REF! -> #REF!
B6: 45853
B9: Gib Stopping
H11: 36
A12: Item | B12: Description | C12: Qty | D12: Unit | E12: Constant | F12: Constant X Unit = Total HRS | G12: $ Lab per Unit | H12: Total Labour | I12: Materials per Unit | J12: Total Materials | K12: Total Labour & Materials | L12: Total Labour & Materials Per Unit | M12: Total | N12: % Complete | O12: Claim
B15: Basement:
B16: Stopping Ceiling Linings:
B17: Level 4 | C17: 107 | D17: m2 | E17: 0.2 | F17: =C17*E17 -> 21.4 | G17: =$H$11*E17 -> 7.2 | H17: =F17*$H$11 -> 770.4 | I17: 0.85 | J17: =C17*I17 -> 90.95 | K17: =SUM(H17,J17) -> 861.35 | L17: =K17/C17 -> 8.05 | M17: =C17*L17 -> 861.35 | N17: 0 | O17: =M17*N17 -> 0
B18: Square Stopping | C18: 166 | D18: m | E18: 0.2 | F18: =C18*E18 -> 33.2 | G18: =$H$11*E18 -> 7.2 | H18: =F18*$H$11 -> 1195.2 | I18: 1.1 | J18: =C18*I18 -> 182.6 | K18: =SUM(H18,J18) -> 1377.8 | L18: =K18/C18 -> 8.3 | M18: =C18*L18 -> 1377.8 | N18: 0 | O18: =M18*N18 -> 0
P19: =SUM(M16:M18) -> 2239.15 | Q19: =P19*SUM($L$202:$L$206) -> 212.71925
B20: Stopping Bulkhead Linings: | C20: Nil | P20: =P19/$M$199 -> 0.013578425 | Q20: =P20*$M$210 -> 106.42325 | R20: =SUM(P19,Q19,Q20) -> 2558.2925 | S20: =R20*1.08 -> 2762.9559
B24: Ground: | C24: `
B25: Stopping Ceiling Linings:
B26: Level 4 | C26: 318 | D26: m2 | E26: 0.2 | F26: =C26*E26 -> 63.6 | G26: =$H$11*E26 -> 7.2 | H26: =F26*$H$11 -> 2289.6 | I26: 0.85 | J26: =C26*I26 -> 270.3 | K26: =SUM(H26,J26) -> 2559.9 | L26: =K26/C26 -> 8.05 | M26: =C26*L26 -> 2559.9 | N26: 0 | O26: =M26*N26 -> 0
B27: Square Stopping | C27: 302 | D27: m | E27: 0.2 | F27: =C27*E27 -> 60.4 | G27: =$H$11*E27 -> 7.2 | H27: =F27*$H$11 -> 2174.4 | I27: 1.1 | J27: =C27*I27 -> 332.2 | K27: =SUM(H27,J27) -> 2506.6 | L27: =K27/C27 -> 8.3 | M27: =C27*L27 -> 2506.6 | N27: 0 | O27: =M27*N27 -> 0
B28: EV Negative to US of Stairs | C28: 23 | D28: m | E28: 0.3 | F28: =C28*E28 -> 6.9 | G28: =$H$11*E28 -> 10.8 | H28: =F28*$H$11 -> 248.4 | I28: 7 | J28: =C28*I28 -> 161 | K28: =SUM(H28,J28) -> 409.4 | L28: =K28/C28 -> 17.8 | M28: =C28*L28 -> 409.4 | N28: 0 | O28: =M28*N28 -> 0
P29: =SUM(M26:M28) -> 5475.9 | Q29: =P29*SUM($L$202:$L$206) -> 520.2105
B30: Stopping Bulkhead Linings: | P30: =P29/$M$199 -> 0.033206394 | Q30: =P30*$M$210 -> 260.26084 | R30: =SUM(P29,Q29,Q30) -> 6256.3713 | S30: =R30*1.08 -> 6756.881
B31: Level 4 | C31: 26 | D31: m2 | E31: 0.2 | F31: =C31*E31 -> 5.2 | G31: =$H$11*E31 -> 7.2 | H31: =F31*$H$11 -> 187.2 | I31: 0.85 | J31: =C31*I31 -> 22.1 | K31: =SUM(H31,J31) -> 209.3 | L31: =K31/C31 -> 8.05 | M31: =C31*L31 -> 209.3 | N31: 0 | O31: =M31*N31 -> 0
B32: External Corner | C32: 39 | D32: m | E32: 0.19 | F32: =C32*E32 -> 7.41 | G32: =$H$11*E32 -> 6.84 | H32: =F32*$H$11 -> 266.76 | I32: 2.02 | J32: =C32*I32 -> 78.78 | K32: =SUM(H32,J32) -> 345.54 | L32: =K32/C32 -> 8.86 | M32: =C32*L32 -> 345.54 | N32: 0 | O32: =M32*N32 -> 0
P33: =SUM(M30:M32) -> 554.84 | Q33: =P33*SUM($L$202:$L$206) -> 52.7098
P34: =P33/$M$199 -> 0.0033646041 | Q34: =P34*$M$210 -> 26.370665 | R34: =SUM(P33,Q33,Q34) -> 633.92046 | S34: =R34*1.08 -> 684.6341
B36: Level 1:
B37: Stopping Ceiling Linings:
B38: Level 4 | C38: 342 | D38: m2 | E38: 0.2 | F38: =C38*E38 -> 68.4 | G38: =$H$11*E38 -> 7.2 | H38: =F38*$H$11 -> 2462.4 | I38: 0.85 | J38: =C38*I38 -> 290.7 | K38: =SUM(H38,J38) -> 2753.1 | L38: =K38/C38 -> 8.05 | M38: =C38*L38 -> 2753.1 | N38: 0 | O38: =M38*N38 -> 0
B39: Square Stopping | C39: 260 | D39: m | E39: 0.2 | F39: =C39*E39 -> 52 | G39: =$H$11*E39 -> 7.2 | H39: =F39*$H$11 -> 1872 | I39: 1.1 | J39: =C39*I39 -> 286 | K39: =SUM(H39,J39) -> 2158 | L39: =K39/C39 -> 8.3 | M39: =C39*L39 -> 2158 | N39: 0 | O39: =M39*N39 -> 0
B40: EV Negative to US of Stairs | C40: 51 | D40: m | E40: 0.3 | F40: =C40*E40 -> 15.3 | G40: =$H$11*E40 -> 10.8 | H40: =F40*$H$11 -> 550.8 | I40: 7 | J40: =C40*I40 -> 357 | K40: =SUM(H40,J40) -> 907.8 | L40: =K40/C40 -> 17.8 | M40: =C40*L40 -> 907.8 | N40: 0 | O40: =M40*N40 -> 0
P41: =SUM(M38:M40) -> 5818.9 | Q41: =P41*SUM($L$202:$L$206) -> 552.7955
B42: Stopping Bulkhead Linings: | P42: =P41/$M$199 -> 0.035286379 | Q42: =P42*$M$210 -> 276.56308 | R42: =SUM(P41,Q41,Q42) -> 6648.2586 | S42: =R42*1.08 -> 7180.1193
B43: Level 4 | C43: 14 | D43: m2 | E43: 0.2 | F43: =C43*E43 -> 2.8 | G43: =$H$11*E43 -> 7.2 | H43: =F43*$H$11 -> 100.8 | I43: 0.85 | J43: =C43*I43 -> 11.9 | K43: =SUM(H43,J43) -> 112.7 | L43: =K43/C43 -> 8.05 | M43: =C43*L43 -> 112.7 | N43: 0 | O43: =M43*N43 -> 0
B44: External Corner | C44: 11 | D44: m | E44: 0.19 | F44: =C44*E44 -> 2.09 | G44: =$H$11*E44 -> 6.84 | H44: =F44*$H$11 -> 75.24 | I44: 2.02 | J44: =C44*I44 -> 22.22 | K44: =SUM(H44,J44) -> 97.46 | L44: =K44/C44 -> 8.86 | M44: =C44*L44 -> 97.46 | N44: 0 | O44: =M44*N44 -> 0
P45: =SUM(M42:M44) -> 210.16 | Q45: =P45*SUM($L$202:$L$206) -> 19.9652
P46: =P45/$M$199 -> 0.0012744308 | Q46: =P46*$M$210 -> 9.9885713 | R46: =SUM(P45,Q45,Q46) -> 240.11377 | S46: =R46*1.08 -> 259.32287
B48: Level 2:
B49: Stopping Ceiling Linings:
B50: Level 4 | C50: 120 | D50: m2 | E50: 0.2 | F50: =C50*E50 -> 24 | G50: =$H$11*E50 -> 7.2 | H50: =F50*$H$11 -> 864 | I50: 0.85 | J50: =C50*I50 -> 102 | K50: =SUM(H50,J50) -> 966 | L50: =K50/C50 -> 8.05 | M50: =C50*L50 -> 966 | N50: 0 | O50: =M50*N50 -> 0
B51: Square Stopping | C51: 156 | D51: m | E51: 0.2 | F51: =C51*E51 -> 31.2 | G51: =$H$11*E51 -> 7.2 | H51: =F51*$H$11 -> 1123.2 | I51: 1.1 | J51: =C51*I51 -> 171.6 | K51: =SUM(H51,J51) -> 1294.8 | L51: =K51/C51 -> 8.3 | M51: =C51*L51 -> 1294.8 | N51: 0 | O51: =M51*N51 -> 0
B52: EV Negative to US of Stairs | C52: 43 | D52: m | E52: 0.3 | F52: =C52*E52 -> 12.9 | G52: =$H$11*E52 -> 10.8 | H52: =F52*$H$11 -> 464.4 | I52: 7 | J52: =C52*I52 -> 301 | K52: =SUM(H52,J52) -> 765.4 | L52: =K52/C52 -> 17.8 | M52: =C52*L52 -> 765.4 | N52: 0 | O52: =M52*N52 -> 0
...

Sheet Skirting with Columns
B1: =Summary!#REF! -> #REF!
B2: =Summary!#REF! -> #REF!
B3: =Summary!#REF! -> #REF!
B6: 45853
B9: Skirting
H11: 52
A12: Item | B12: Description | C12: Qty | D12: Unit | E12: Constant | F12: Constant X Unit = Total HRS | G12: $ Lab per Unit | H12: Total Labour | I12: Materials per Unit | J12: Total Materials | K12: Total Labour & Materials | L12: Total Labour & Materials Per Unit | M12: Total | N12: % Complete | O12: Claim
B15: Basement:
B17: SK1 Type - 90 x 10 Timber Flat | C17: 135 | D17: m | E17: 0.2 | F17: =C17*E17 -> 27 | G17: =$H$11*E17 -> 10.4 | H17: =F17*$H$11 -> 1404 | I17: 7.06 | J17: =C17*I17 -> 953.1 | K17: =SUM(H17,J17) -> 2357.1 | L17: =K17/C17 -> 17.46 | M17: =C17*L17 -> 2357.1 | N17: 0 | O17: =M17*N17 -> 0
B18: SK2 Type | C18: Nil, Tile by Others
P19: =SUM(M14:M18) -> 2357.1 | Q19: =P19*SUM($L$98:$L$102) -> 223.9245
P20: =P19/$M$95 -> 0.070570641 | Q20: =P20*$M$106 -> 45.428086 | R20: =SUM(P19,Q19,Q20) -> 2626.4526 | S20: =R20*1.08 -> 2836.5688 | Y20: 0.5
B21: Ground: | U21: Tape/Pins | V21: Glue | X21: 0.05 | Y21: Loadin
B22: SK1 Type - 90 x 10 Timber Flat | C22: 97 | D22: m | E22: 0.2 | F22: =C22*E22 -> 19.4 | G22: =$H$11*E22 -> 10.4 | H22: =F22*$H$11 -> 1008.8 | I22: =Z22 -> 7.0625 | J22: =C22*I22 -> 685.0625 | K22: =SUM(H22,J22) -> 1693.8625 | L22: =K22/C22 -> 17.4625 | M22: =C22*L22 -> 1693.8625 | N22: 0 | O22: =M22*N22 -> 0 | T22: 5 | U22: 0.5 | V22: 0.75 | W22: =SUM(T22:V22) -> 6.25 | X22: =W22*1.05 -> 6.5625 | Y22: =$Y$20 -> 0.5 | Z22: =SUM(X22:Y22) -> 7.0625 | AA22: =C22*Y22 -> 48.5
B23: SK2 Type | C23: Nil, Tile by Others
B24: SK3 Type - 100mm Flat | C24: 27 | D24: m | E24: 0.25 | F24: =C24*E24 -> 6.75 | G24: =$H$11*E24 -> 13 | H24: =F24*$H$11 -> 351 | I24: =Z24 -> 19.8095 | J24: =C24*I24 -> 534.8565 | K24: =SUM(H24,J24) -> 885.8565 | L24: =K24/C24 -> 32.8095 | M24: =C24*L24 -> 885.8565 | N24: 0 | O24: =M24*N24 -> 0 | T24: 14.17 | U24: 2.72 | V24: 1.5 | W24: =SUM(T24:V24) -> 18.39 | X24: =W24*1.05 -> 19.3095 | Y24: =$Y$20 -> 0.5 | Z24: =SUM(X24:Y24) -> 19.8095 | AA24: =C24*Y24 -> 13.5
B25: SK4 Type - 100mm Flat | C25: 15 | D25: m | E25: 0.25 | F25: =C25*E25 -> 3.75 | G25: =$H$11*E25 -> 13 | H25: =F25*$H$11 -> 195 | I25: =Z25 -> 19.8095 | J25: =C25*I25 -> 297.1425 | K25: =SUM(H25,J25) -> 492.1425 | L25: =K25/C25 -> 32.8095 | M25: =C25*L25 -> 492.1425 | N25: 0 | O25: =M25*N25 -> 0 | T25: 14.17 | U25: 2.72 | V25: 1.5 | W25: =SUM(T25:V25) -> 18.39 | X25: =W25*1.05 -> 19.3095 | Y25: =$Y$20 -> 0.5 | Z25: =SUM(X25:Y25) -> 19.8095 | AA25: =C25*Y25 -> 7.5
B26: SK5 Type - 25mm Flat | C26: 21 | D26: m | E26: 0.25 | F26: =C26*E26 -> 5.25 | G26: =$H$11*E26 -> 13 | H26: =F26*$H$11 -> 273 | I26: =Z26 -> 14.4335 | J26: =C26*I26 -> 303.1035 | K26: =SUM(H26,J26) -> 576.1035 | L26: =K26/C26 -> 27.4335 | M26: =C26*L26 -> 576.1035 | N26: 0 | O26: =M26*N26 -> 0 | T26: 9.8 | U26: 2.72 | V26: 0.75 | W26: =SUM(T26:V26) -> 13.27 | X26: =W26*1.05 -> 13.9335 | Y26: =$Y$20 -> 0.5 | Z26: =SUM(X26:Y26) -> 14.4335 | AA26: =C26*Y26 -> 10.5 | AB26: =SUM(AA22:AA26) -> 80
B28: SK4 - Plastered Column | C28: 3 | D28: no | E28: 0.5 | F28: =C28*E28 -> 1.5 | G28: =$H$11*E28 -> 26 | H28: =F28*$H$11 -> 78 | I28: 58 | J28: =C28*I28 -> 174 | K28: =SUM(H28,J28) -> 252 | L28: =K28/C28 -> 84 | M28: =C28*L28 -> 252 | N28: 0 | O28: =M28*N28 -> 0
B29: SK5 - Other Columns | C29: 13 | D29: no | E29: 0.5 | F29: =C29*E29 -> 6.5 | G29: =$H$11*E29 -> 26 | H29: =F29*$H$11 -> 338 | I29: 48 | J29: =C29*I29 -> 624 | K29: =SUM(H29,J29) -> 962 | L29: =K29/C29 -> 74 | M29: =C29*L29 -> 962 | N29: 0 | O29: =M29*N29 -> 0
P30: =SUM(M22:M29) -> 4861.965 | Q30: =P30*SUM($L$98:$L$102) -> 461.88668
B31: Level 1: | P31: =P30/$M$95 -> 0.14556531 | Q31: =P31*$M$106 -> 93.704028 | R31: =SUM(P30,Q30,Q31) -> 5417.5557 | S31: =R31*1.08 -> 5850.9602
B32: SK1 Type - 90 x 10 Timber Flat | C32: 28 | D32: m | E32: 0.2 | F32: =C32*E32 -> 5.6 | G32: =$H$11*E32 -> 10.4 | H32: =F32*$H$11 -> 291.2 | I32: 7.06 | J32: =C32*I32 -> 197.68 | K32: =SUM(H32,J32) -> 488.88 | L32: =K32/C32 -> 17.46 | M32: =C32*L32 -> 488.88 | N32: 0 | O32: =M32*N32 -> 0
B33: SK2 Type | C33: Nil, Tile by Others
B34: SK3 Type - 100mm Flat | C34: 9 | D34: m | E34: 0.25 | F34: =C34*E34 -> 2.25 | G34: =$H$11*E34 -> 13 | H34: =F34*$H$11 -> 117 | I34: 19.81 | J34: =C34*I34 -> 178.29 | K34: =SUM(H34,J34) -> 295.29 | L34: =K34/C34 -> 32.81 | M34: =C34*L34 -> 295.29 | N34: 0 | O34: =M34*N34 -> 0
B35: SK4 Type - 100mm Flat | C35: Nil
B36: SK5 Type - 25mm Flat | C36: 83 | D36: m | E36: 0.25 | F36: =C36*E36 -> 20.75 | G36: =$H$11*E36 -> 13 | H36: =F36*$H$11 -> 1079 | I36: 14.43 | J36: =C36*I36 -> 1197.69 | K36: =SUM(H36,J36) -> 2276.69 | L36: =K36/C36 -> 27.43 | M36: =C36*L36 -> 2276.69 | N36: 0 | O36: =M36*N36 -> 0
B38: SK5 - Other Columns | C38: 20 | D38: no | E38: 0.5 | F38: =C38*E38 -> 10 | G38: =$H$11*E38 -> 26 | H38: =F38*$H$11 -> 520 | I38: 58 | J38: =C38*I38 -> 1160 | K38: =SUM(H38,J38) -> 1680 | L38: =K38/C38 -> 84 | M38: =C38*L38 -> 1680 | N38: 0 | O38: =M38*N38 -> 0
P39: =SUM(M32:M38) -> 4740.86 | Q39: =P39*SUM($L$98:$L$102) -> 450.3817
P40: =P39/$M$95 -> 0.14193947 | Q40: =P40*$M$106 -> 91.369987 | R40: =SUM(P39,Q39,Q40) -> 5282.6117 | S40: =R40*1.08 -> 5705.2206
B41: Level 2:
B42: SK1 Type - 90 x 10 Timber Flat | C42: 28 | D42: m | E42: 0.2 | F42: =C42*E42 -> 5.6 | G42: =$H$11*E42 -> 10.4 | H42: =F42*$H$11 -> 291.2 | I42: 7.06 | J42: =C42*I42 -> 197.68 | K42: =SUM(H42,J42) -> 488.88 | L42: =K42/C42 -> 17.46 | M42: =C42*L42 -> 488.88 | N42: 0 | O42: =M42*N42 -> 0
B43: SK2 Type | C43: Nil, Tile by Others
B44: SK3 Type - 100mm Flat | C44: 9 | D44: m | E44: 0.25 | F44: =C44*E44 -> 2.25 | G44: =$H$11*E44 -> 13 | H44: =F44*$H$11 -> 117 | I44: 19.81 | J44: =C44*I44 -> 178.29 | K44: =SUM(H44,J44) -> 295.29 | L44: =K44/C44 -> 32.81 | M44: =C44*L44 -> 295.29 | N44: 0 | O44: =M44*N44 -> 0
B45: SK4 Type - 100mm Flat | C45: Nil
B46: SK5 Type - 25mm Flat | C46: 83 | D46: m | E46: 0.25 | F46: =C46*E46 -> 20.75 | G46: =$H$11*E46 -> 13 | H46: =F46*$H$11 -> 1079 | I46: 14.43 | J46: =C46*I46 -> 1197.69 | K46: =SUM(H46,J46) -> 2276.69 | L46: =K46/C46 -> 27.43 | M46: =C46*L46 -> 2276.69 | N46: 0 | O46: =M46*N46 -> 0
B48: SK5 - Other Columns | C48: 20 | D48: no | E48: 0.5 | F48: =C48*E48 -> 10 | G48: =$H$11*E48 -> 26 | H48: =F48*$H$11 -> 520 | I48: 58 | J48: =C48*I48 -> 1160 | K48: =SUM(H48,J48) -> 1680 | L48: =K48/C48 -> 84 | M48: =C48*L48 -> 1680 | N48: 0 | O48: =M48*N48 -> 0
P49: =SUM(M42:M48) -> 4740.86 | Q49: =P49*SUM($L$98:$L$102) -> 450.3817
P50: =P49/$M$95 -> 0.14193947 | Q50: =P50*$M$106 -> 91.369987 | R50: =SUM(P49,Q49,Q50) -> 5282.6117 | S50: =R50*1.08 -> 5705.2206
B51: Level 3:
...

Sheet PROV SUM PS1 & PS4 _25_8
B1: =Summary!#REF! -> #REF!
B2: =Summary!#REF! -> #REF!
B3: =Summary!#REF! -> #REF!
B6: =Summary!#REF! -> #REF!
B9: PROVISIONAL SUM: PS1 Design & PS4 Certificate for Interior Steel Stud Partition
H11: 52
A12: Item | B12: Description | C12: Qty | D12: Unit | E12: Constant | F12: Constant X Unit = Total HRS | G12: $ Lab per Unit | H12: Total Labour | I12: Materials per Unit | J12: Total Materials | K12: Total Labour & Materials | L12: Total Labour & Materials Per Unit | M12: Total | N12: Total | O12: Claim
Q13: 1.06 | R13: 1.08
B15: Suspended Ceiling Design | C15: By CBC | Q15: =M15*$Q$13 -> 0 | R15: =Q15*$R$13 -> 0 | S15: 13250
B16: Steel Stud Partition Design | C16: 1 | D16: item | F16: =C16*E16 -> 0 | G16: =$H$11*E16 -> 0 | H16: =F16*$H$11 -> 0 | I16: 2904 | J16: =C16*I16 -> 2904 | K16: =SUM(H16,J16) -> 2904 | L16: =K16/C16 -> 2904 | M16: =C16*L16 -> 2904 | N16: 3500 | Q16: =M16*$Q$13 -> 3078.24 | R16: =Q16*$R$13 -> 3324.4992 | S16: 3500 | U16: 2950
B17: Construction Monitoring for PS4 to Above | C17: 8 | D17: no | F17: =C17*E17 -> 0 | G17: =$H$11*E17 -> 0 | H17: =F17*$H$11 -> 0 | I17: 675 | J17: =C17*I17 -> 5400 | K17: =SUM(H17,J17) -> 5400 | L17: =K17/C17 -> 675 | M17: =C17*L17 -> 5400 | N17: 6250 | Q17: =M17*$Q$13 -> 5724 | R17: =Q17*$R$13 -> 6181.92 | S17: 6250 | U17: 5400
