Workbook

Sheet Summary
B1: Ceilings Unlimited
B2: Craigs Investment Partners - Fitout
B3: Tauranga
B5: 46043
B6: Summary
B7: Clarifications:
B8: * No allowance for access equipment over 3000 or any scaffold/access to stair wells, atrium voids or lift shafts including edge protection. To be supplied by Main Contractor
B9: * We note most material sizes will not fit within the lift indicated for use. Pricing is based on all materials being lifted/removed via crane or hiab to respective Levels to an access point/loadin platform then through facade. Removal/reinstatement of facade as well as Crane/Hiab of materials up and down, Access point/loadin platform to be provided by main contractor along with any associated Traffic Management costs that may be required.
B10: * This trade pricing is based on the acceptance as a package and if individual trades were selected we would need to be contacted to discuss before acceptance.
B11: * Pricing has been split across levels but based on all works proceeding. Removal of items may come at cost premium affecting cost to other levels.
B12: * Based on Retentions on a sliding scale basis.
B13: * No allowance for detailed drawings/shop drawings, Prototypes, Samples and Resource and Consent fees etc. By Others.
B14: * Pricing is based on Brevity PS1 Designs. We have not allowed for any construction monitoring or PS4 sign off, if required to carried out by othes.
B15: * Allowed for works within normal works hours Monday to Friday 7.30am - 5pm.
B16: * Pricing based on sliding scale retention basis.
B17: * Rubbish disposal to be provided by main contractor/others on each level or works
... B114: * Detailed Programming to be to be discussed prior to acceptance.
B115: * Pricing validity as per cover letter. We have not allowed for any escalation of costs after this point and will be claimed as a variation accordingly if required (We have taken into consideration known price increases on Potters Aluminum and Gib Linings in the first half of 2026). | J115: Level 4 | K115: Level 5 | L115: Level 6
B117: Suspended Ceilings | C117: ='Suspended Ceilings'!M141 -> 241937 | I117: =B117 -> Suspended Ceilings | J117: ='Suspended Ceilings'!Q143 -> 12484.965 | K117: ='Suspended Ceilings'!Q145 -> 2860.8406 | L117: ='Suspended Ceilings'!Q147 -> 226590.94 | O117: =P117-C117 -> -0.25866122 | P117: =SUM(J117:L117) -> 241936.74
B119: Partitions | C119: ='Partitions SPEC Rates'!M179 -> 147472 | I119: =B119 -> Partitions | J119: ='Partitions SPEC Rates'!Q181 -> 49494.234 | K119: ='Partitions SPEC Rates'!Q183 -> 41336.657 | L119: ='Partitions SPEC Rates'!Q185 -> 56640.165 | O119: =P119-C119 -> -0.94303941 | P119: =SUM(J119:L119) -> 147471.06
B121: Insulation | C121: =Insulation!M113 -> 41680 | I121: =B121 -> Insulation | J121: =Insulation!Q115 -> 12987.284 | K121: =Insulation!Q117 -> 9111.1218 | L121: =Insulation!Q119 -> 19581.414 | O121: =P121-C121 -> -0.18003321 | P121: =SUM(J121:L121) -> 41679.82
B123: Gib Wall and Ceiling Linings | C123: ='Gib Linings'!M211 -> 186146 | I123: =B123 -> Gib Wall and Ceiling Linings | J123: ='Gib Linings'!Q213 -> 48509.091 | K123: ='Gib Linings'!Q215 -> 44677.051 | L123: ='Gib Linings'!Q217 -> 92958.928 | O123: =P123-C123 -> -0.929105 | P123: =SUM(J123:L123) -> 186145.07
B125: Stopping to Gib Wall and Ceilings | C125: =Stopping!M90 -> 66579 | I125: =B125 -> Stopping to Gib Wall and Ceilings | J125: =Stopping!Q92 -> 18949.133 | K125: =Stopping!Q94 -> 15992.349 | L125: =Stopping!Q96 -> 31637.33 | O125: =P125-C125 -> -0.187854 | P125: =SUM(J125:L125) -> 66578.812
B127: Potters Rigitone Matrix Ceiling Lining | C127: ='Potters Rigitone Matrix'!M61 -> 48735 | I127: =B127 -> Potters Rigitone Matrix Ceiling Lining | J127: 0 | K127: 0 | L127: ='Potters Rigitone Matrix'!M61 -> 48735 | O127: =P127-C127 -> 0 | P127: =SUM(J127:L127) -> 48735
B129: Ambitec (PF-01 and PF-02 to Wall and Bulkheads Only) | C129: =Ambitec!M83 -> 135513 | I129: =B129 -> Ambitec (PF-01 and PF-02 to Wall and Bulkheads Only) | J129: =Ambitec!S85 -> 38178.604 | K129: =Ambitec!S87 -> 29195.403 | L129: =Ambitec!S89 -> 68138.135 | O129: =P129-C129 -> -0.8583075 | P129: =SUM(J129:L129) -> 135512.14
B131: Featurecraft (TB-01 and TB-02) | C131: =Featurecraft!M86 -> 687105 | I131: =B131 -> Featurecraft (TB-01 and TB-02) | J131: =Featurecraft!Q88 -> 276610.12 | K131: =Featurecraft!Q90 -> 201242.99 | L131: =Featurecraft!Q92 -> 209251.88 | O131: =P131-C131 -> -0.0048782172 | P131: =SUM(J131:L131) -> 687105
B133: Potters Aluminium, Doors, Glazing and Skirting | C133: ='Potters Aluminium and Glazing'!M426 -> 326715 | I133: =B133 -> Potters Aluminium, Doors, Glazing and Skirting | J133: ='Potters Aluminium and Glazing'!Q428 -> 95019.673 | K133: ='Potters Aluminium and Glazing'!Q430 -> 80525.42 | L133: ='Potters Aluminium and Glazing'!Q432 -> 151169.61 | O133: =P133-C133 -> -0.2990088 | P133: =SUM(J133:L133) -> 326714.7
B135: Wall Covering: Asona Quicklock (FP-01) | C135: ='Asona Quicklock'!M118 -> 138546 | I135: =B135 -> Wall Covering: Asona Quicklock (FP-01) | J135: ='Asona Quicklock'!Q120 -> 31037.57 | K135: ='Asona Quicklock'!Q122 -> 40717.699 | L135: ='Asona Quicklock'!Q124 -> 66790.113 | O135: =P135-C135 -> -0.61848 | P135: =SUM(J135:L135) -> 138545.38
B139: Total of all items priced | F139: =SUM(C117:C135) -> 2020428 | J139: =SUM(J116:J135) -> 583270.68 | K139: =SUM(K116:K135) -> 465659.53 | L139: =SUM(L116:L135) -> 971493.51 | O139: =P139-C139 -> 2020423.7 | P139: =SUM(J139:L139) -> 2020423.7
B140: * No allowance for GST
C146: =B117 -> Suspended Ceilings | F146: =B119 -> Partitions | G146: =B121 -> Insulation | H146: =B123 -> Gib Wall and Ceiling Linings | I146: =B125 -> Stopping to Gib Wall and Ceilings | J146: =B127 -> Potters Rigitone Matrix Ceiling Lining | K146: =B129 -> Ambitec (PF-01 and PF-02 to Wall and Bulkheads Only) | L146: =B131 -> Featurecraft (TB-01 and TB-02) | M146: =B133 -> Potters Aluminium, Doors, Glazing and Skirting | N146: =B135 -> Wall Covering: Asona Quicklock (FP-01)
B148: P&G - Admin / Supervision | C148: ='Suspended Ceilings'!M127 -> 4515.5375 | F148: =Partitions!M169 -> 2939.5963 | G148: =Insulation!M99 -> 773.86729 | H148: ='Gib Linings'!M197 -> 3463.3787 | I148: =Stopping!M76 -> 1212.502 | J148: ='Potters Rigitone Matrix'!M47 -> 901.82985 | K148: =Ambitec!M69 -> 2593.9368 | L148: =Featurecraft!M72 -> 13094.444 | M148: ='Potters Aluminium and Glazing'!M412 -> 6142.5314 | N148: ='Asona Quicklock'!M104 -> 2656.472 | O148: =SUM(C148:N148) -> 38294.096
B149: P&G - Site Establishment | C149: ='Suspended Ceilings'!M129 -> 2202.7012 | F149: =Partitions!M171 -> 1433.9494 | G149: =Insulation!M101 -> 377.49624 | H149: ='Gib Linings'!M199 -> 1689.453 | I149: =Stopping!M78 -> 591.4644 | J149: ='Potters Rigitone Matrix'!M49 -> 439.917 | K149: =Ambitec!M71 -> 1265.335 | L149: =Featurecraft!M74 -> 6387.5337 | M149: ='Potters Aluminium and Glazing'!M414 -> 2996.3568 | N149: ='Asona Quicklock'!M106 -> 1295.84 | O149: =SUM(C149:N149) -> 18680.047
B150: P&G - Access Equip | C150: ='Suspended Ceilings'!M131 -> 550.6753 | F150: =Partitions!M173 -> 358.48735 | G150: =Insulation!M103 -> 94.37406 | H150: ='Gib Linings'!M201 -> 422.36325 | I150: =Stopping!M80 -> 147.8661 | J150: ='Potters Rigitone Matrix'!M51 -> 109.97925 | K150: =Ambitec!M73 -> 316.33375 | L150: =Featurecraft!M76 -> 1596.8834 | M150: ='Potters Aluminium and Glazing'!M416 -> 749.08919 | N150: ='Asona Quicklock'!M108 -> 323.96 | O150: =SUM(C150:N150) -> 4670.0117
B151: P&G - Parking | C151: ='Suspended Ceilings'!M133 -> 2876.91 | F151: =Partitions!M175 -> 2904.0347 | G151: =Insulation!M105 -> 699.705 | H151: ='Gib Linings'!M203 -> 2760.525 | I151: =Stopping!M82 -> 2310.12 | J151: ='Potters Rigitone Matrix'!M53 -> 970.3125 | K151: =Ambitec!M75 -> 220.5 | L151: =Featurecraft!M78 -> 4037.3325 | M151: ='Potters Aluminium and Glazing'!M418 -> 1633.2049 | N151: ='Asona Quicklock'!M110 -> 0 | O151: =SUM(C151:N151) -> 18412.645
B152: P&G | C152: ='Suspended Ceilings'!M135 -> 0 | F152: =Partitions!M177 -> 0 | G152: =Insulation!M107 -> 0 | H152: ='Gib Linings'!M205 -> 0 | I152: =Stopping!M84 -> 0 | J152: ='Potters Rigitone Matrix'!M55 -> 0 | K152: =Ambitec!M77 -> 0 | L152: =Featurecraft!M80 -> 0 | M152: ='Potters Aluminium and Glazing'!M420 -> 0 | N152: ='Asona Quicklock'!M112 -> 0 | O152: =SUM(C152:N152) -> 0
B153: Margin | C153: ='Suspended Ceilings'!M139 -> 11520.797 | F153: =Partitions!M181 -> 7551.5504 | G153: =Insulation!M111 -> 1984.7533 | H153: ='Gib Linings'!M209 -> 8864.051 | I153: =Stopping!M88 -> 3170.4196 | J153: ='Potters Rigitone Matrix'!M59 -> 2320.6869 | K153: =Ambitec!M81 -> 4582.5362 | L153: =Featurecraft!M84 -> 23235.435 | M153: ='Potters Aluminium and Glazing'!M424 -> 15557.843 | N153: ='Asona Quicklock'!M116 -> 4685.1095 | O153: =SUM(C153:N153) -> 83473.182
B154: Total | C154: =SUM(C148:C153) -> 21666.621 | F154: =SUM(F148:F153) -> 15187.618 | G154: =SUM(G148:G153) -> 3930.1959 | H154: =SUM(H148:H153) -> 17199.771 | I154: =SUM(I148:I153) -> 7432.3721 | J154: =SUM(J148:J153) -> 4742.7255 | K154: =SUM(K148:K153) -> 8978.6417 | L154: =SUM(L148:L153) -> 48351.628 | M154: =SUM(M148:M153) -> 27079.025 | N154: =SUM(N148:N153) -> 8961.3815
P155: Hours/Week | S155: Day
B156: Labour Hours to Above | S156: 5
...

Sheet Suspended Ceilings
B1: =Summary!B1 -> Ceilings Unlimited
B2: =Summary!B2 -> Craigs Investment Partners - Fitout
B3: =Summary!B3 -> Tauranga
B6: =Summary!B5 -> 46043
B9: =Summary!B117 -> Suspended Ceilings
H11: 50
A12: Item | B12: Description | C12: Qty | D12: Unit | E12: Constant | F12: Constant X Unit = Total HRS | G12: $ Lab per Unit | H12: Total Labour | I12: Materials per Unit | J12: Total Materials | K12: Total Labour & Materials | L12: Total Labour & Materials Per Unit | M12: Total | N12: % Complete | O12: Claim
B14: Level 4:
B16: (C-01A) | C16: Nil
B18: (C-01B) | C18: Basebuild - By Others | E18: 661m2
B20: (C-02) Concealed Ceiling Grid @ 600 crs | C20: 45 | D20: m2 | E20: 0.47 | F20: =C20*E20 -> 21.15 | G20: =$H$11*E20 -> 23.5 | H20: =F20*$H$11 -> 1057.5 | I20: 30.68 | J20: =C20*I20 -> 1380.6 | K20: =SUM(H20,J20) -> 2438.1 | L20: =K20/C20 -> 54.18 | M20: =C20*L20 -> 2438.1 | N20: 0 | O20: =M20*N20 -> 0
B21: Perimeter to Above | C21: 116 | D21: m
B22: (C-02) 530 x 530 Set Bead Ceiling Hatches to Above | C22: 4 | D22: no | E22: 3 | F22: =C22*E22 -> 12 | G22: =$H$11*E22 -> 150 | H22: =F22*$H$11 -> 600 | I22: 112 | J22: =C22*I22 -> 448 | K22: =SUM(H22,J22) -> 1048 | L22: =K22/C22 -> 262 | M22: =C22*L22 -> 1048 | N22: 0 | O22: =M22*N22 -> 0
B24: (C-04) 50mm Autexquiet Space (AP04) | C24: Nil, By Others | E24: 183m2 | F24: Basebuild?? Colour??
B26: Bulkhead 2900 - 3900 (Detail 9 - ID 502) | C26: 41 | D26: m | E26: =WORKINGS_Ceilngs!G297 -> 1.55 | F26: =C26*E26 -> 63.55 | G26: =$H$11*E26 -> 77.5 | H26: =F26*$H$11 -> 3177.5 | I26: =WORKINGS_Ceilngs!K297 -> 52.731917 | J26: =C26*I26 -> 2162.0086 | K26: =SUM(H26,J26) -> 5339.5086 | L26: =K26/C26 -> 130.23192 | M26: =C26*L26 -> 5339.5086 | N26: 0 | O26: =M26*N26 -> 0
B27: Bulkhead 2900 - 3900 (Detail 4 - ID 502) | C27: 13 | D27: m | E27: =WORKINGS_Ceilngs!G297 -> 1.55 | F27: =C27*E27 -> 20.15 | G27: =$H$11*E27 -> 77.5 | H27: =F27*$H$11 -> 1007.5 | I27: =WORKINGS_Ceilngs!K297 -> 52.731917 | J27: =C27*I27 -> 685.51492 | K27: =SUM(H27,J27) -> 1693.0149 | L27: =K27/C27 -> 130.23192 | M27: =C27*L27 -> 1693.0149 | N27: 0 | O27: =M27*N27 -> 0
B28: Bulkhead 2900 - 3900 (Detail 4 - ID 401) | C28: 4 | D28: m | E28: =WORKINGS_Ceilngs!G317 -> 1.57 | F28: =C28*E28 -> 6.28 | G28: =$H$11*E28 -> 78.5 | H28: =F28*$H$11 -> 314 | I28: =WORKINGS_Ceilngs!K317 -> 133.56292 | J28: =C28*I28 -> 534.25167 | K28: =SUM(H28,J28) -> 848.25167 | L28: =K28/C28 -> 212.06292 | M28: =C28*L28 -> 848.25167 | N28: 0 | O28: =M28*N28 -> 0
B31: Level 5:
B33: (C-01A) | C33: Nil
B35: (C-01B) | C35: Basebuild - By Others | E35: 661m2
B37: (C-04) 50mm Autexquiet Space (AP04) | C37: Nil, By Others | E37: 98m2 | F37: Basebuild?? Colour??
B39: Bulkhead 2900 - 3900 (Detail 9 - ID 502) | C39: 20 | D39: m | E39: =WORKINGS_Ceilngs!G297 -> 1.55 | F39: =C39*E39 -> 31 | G39: =$H$11*E39 -> 77.5 | H39: =F39*$H$11 -> 1550 | I39: =WORKINGS_Ceilngs!K297 -> 52.731917 | J39: =C39*I39 -> 1054.6383 | K39: =SUM(H39,J39) -> 2604.6383 | L39: =K39/C39 -> 130.23192 | M39: =C39*L39 -> 2604.6383 | N39: 0 | O39: =M39*N39 -> 0
B42: Level 6:
B44: (C-01A) | C44: Basebuild - By Others | E44: 39m2
B46: (C-01B) | C46: Basebuild - By Others | E46: 102m2
B48: (C-02) Concealed Grid @ 600 crs | C48: 4 | D48: m2 | E48: 0.68 | F48: =C48*E48 -> 2.72 | G48: =$H$11*E48 -> 34 | H48: =F48*$H$11 -> 136 | I48: 69.28 | J48: =C48*I48 -> 277.12 | K48: =SUM(H48,J48) -> 413.12 | L48: =K48/C48 -> 103.28 | M48: =C48*L48 -> 413.12 | N48: 0 | O48: =M48*N48 -> 0
B49: Perimeter to Above | C49: 19 | D49: m
B51: (C-03) Concealed Grid @ 600 crs | C51: 249 | D51: m2 | E51: 0.33 | F51: =C51*E51 -> 82.17 | G51: =$H$11*E51 -> 16.5 | H51: =F51*$H$11 -> 4108.5 | I51: 20.56 | J51: =C51*I51 -> 5119.44 | K51: =SUM(H51,J51) -> 9227.94 | L51: =K51/C51 -> 37.06 | M51: =C51*L51 -> 9227.94 | N51: 0 | O51: =M51*N51 -> 0
B52: Perimeter to Above | C52: 300 | D52: m
B53: Trim Out Service Penetrations | C53: 47 | D53: no | E53: 1 | F53: =C53*E53 -> 47 | G53: =$H$11*E53 -> 50 | H53: =F53*$H$11 -> 2350 | I53: 20 | J53: =C53*I53 -> 940 | K53: =SUM(H53,J53) -> 3290 | L53: =K53/C53 -> 70 | M53: =C53*L53 -> 3290 | N53: 0 | O53: =M53*N53 -> 0
B54: (C-03) 530 x 530 Set Bead Ceiling Hatches to Above | C54: 30 | D54: no | E54: 3 | F54: =C54*E54 -> 90 | G54: =$H$11*E54 -> 150 | H54: =F54*$H$11 -> 4500 | I54: 112 | J54: =C54*I54 -> 3360 | K54: =SUM(H54,J54) -> 7860 | L54: =K54/C54 -> 262 | M54: =C54*L54 -> 7860 | N54: 0 | O54: =M54*N54 -> 0
B56: Linear Tray Items in C-03 | C56: 34 | D56: m | E56: Workings Below
B57: 12mm MDF Substrate and Packing | C57: 34 | D57: m | E57: 0.5 | F57: =C57*E57 -> 17 | G57: =$H$11*E57 -> 25 | H57: =F57*$H$11 -> 850 | I57: 30 | J57: =C57*I57 -> 1020 | K57: =SUM(H57,J57) -> 1870 | L57: =K57/C57 -> 55 | M57: =C57*L57 -> 1870 | N57: 0 | O57: =M57*N57 -> 0
B58: Trim Services into Above | C58: 34 | D58: m | E58: 0.25 | F58: =C58*E58 -> 8.5 | G58: =$H$11*E58 -> 12.5 | H58: =F58*$H$11 -> 425 | I58: 0 | J58: =C58*I58 -> 0 | K58: =SUM(H58,J58) -> 425 | L58: =K58/C58 -> 12.5 | M58: =C58*L58 -> 425 | N58: 0 | O58: =M58*N58 -> 0
B59: Paint Shadowline/Edge of MDF | C59: 70 | D59: m | E59: 0.1 | F59: =C59*E59 -> 7 | G59: =$H$11*E59 -> 5 | H59: =F59*$H$11 -> 350 | I59: 2 | J59: =C59*I59 -> 140 | K59: =SUM(H59,J59) -> 490 | L59: =K59/C59 -> 7 | M59: =C59*L59 -> 490 | N59: 0 | O59: =M59*N59 -> 0
B60: Tray ex Industrial Sheet Metals | C60: 34 | D60: m | E60: 0 | F60: =C60*E60 -> 0 | G60: =$H$11*E60 -> 0 | H60: =F60*$H$11 -> 0 | I60: 100 | J60: =C60*I60 -> 3400 | K60: =SUM(H60,J60) -> 3400 | L60: =K60/C60 -> 100 | M60: =C60*L60 -> 3400 | N60: 0 | O60: =M60*N60 -> 0
B61: Install Tray | C61: 34 | D61: m | E61: 0.5 | F61: =C61*E61 -> 17 | G61: =$H$11*E61 -> 25 | H61: =F61*$H$11 -> 850 | I61: 2.5 | J61: =C61*I61 -> 85 | K61: =SUM(H61,J61) -> 935 | L61: =K61/C61 -> 27.5 | M61: =C61*L61 -> 935 | N61: 0 | O61: =M61*N61 -> 0
B63: (C-06) Illuminated Membrane and Frame | C63: Nil, Supplied and Installed By Others
B64: Trim Openings to Above | C64: 4 | D64: no | E64: 4.5 | F64: =C64*E64 -> 18 | G64: =$H$11*E64 -> 225 | H64: =F64*$H$11 -> 900 | I64: 50 | J64: =C64*I64 -> 200 | K64: =SUM(H64,J64) -> 1100 | L64: =K64/C64 -> 275 | M64: =C64*L64 -> 1100 | N64: 0 | O64: =M64*N64 -> 0
B65: Bronze Finishing Trim to Above, BR-01 (ID 363) | C65: 4 | D65: no | E65: 5 | F65: =C65*E65 -> 20 | G65: =$H$11*E65 -> 250 | H65: =F65*$H$11 -> 1000 | I65: 572 | J65: =C65*I65 -> 2288 | K65: =SUM(H65,J65) -> 3288 | L65: =K65/C65 -> 822 | M65: =C65*L65 -> 3288 | N65: 0 | O65: =M65*N65 -> 0
...

Sheet WORKINGS_Ceilngs
P1: Loadin
B2: 3 Mains and 5 Nogs | C2: Mains | D2: 3 | E2: 20 | F2: =D2*E2 -> 60 | G2: 20 | H2: =F2*G2 -> 1200 | K2: C-08 | L2: 164 | M2: m2 | N2: 223656 | O2: =N2/L2 -> 1363.7561 | P2: 7 | Q2: =O2+P2 -> 1370.7561 | R2: =L2*Q2 -> 224804
C3: Nogs | D3: 5 | E3: 60 | F3: =D3*E3 -> 300 | G3: 6.5 | H3: =F3*G3 -> 1950 | I3: =SUM(H2:H3) -> 3150 | K3: C-10 | L3: 33 | M3: m2 | N3: 45004 | O3: =N3/L3 -> 1363.7576 | P3: 7 | Q3: =O3+P3 -> 1370.7576 | R3: =L3*Q3 -> 45235
B5: 1 Mains and 1 Nogs | C5: Mains | D5: 1 | E5: 20 | F5: =D5*E5 -> 20 | G5: 20 | H5: =F5*G5 -> 400 | N5: =SUM(N2:N4) -> 268660 | R5: =SUM(R2:R4) -> 270039
C6: Nogs | D6: 1 | E6: 60 | F6: =D6*E6 -> 60 | G6: 6.5 | H6: =F6*G6 -> 390 | I6: =SUM(H5:H6) -> 790
G8: Wires | O8: 1.05 | R8: Loadin
B9: Suspended system Rondo | F9: Dis between TCR | G9: Across TCR wire | K9: C-08 | L9: 164 | M9: m2 | N9: 227 | O9: =N9*O8 -> 238.35 | P9: 70.73 | Q9: 31 | R9: 7 | S9: =SUM(P9:R9) -> 108.73 | T9: =O9*S9 -> 25915.796
B10: 28mm furring channel @ | C10: 0.6 | E10: TCR spacing | F10: 1.2 | G10: 1.2 | K10: C-10 | L10: 33 | M10: m2 | N10: 46 | O10: =N10*O8 -> 48.3 | P10: 70.73 | Q10: 31 | R10: 7 | S10: =SUM(P10:R10) -> 108.73 | T10: =O10*S10 -> 5251.659
B11: 40 x 40 | C11: 27
B12: M2 | C12: 36 | E12: Total furring LM | F12: Total Perim LM | G12: M2 of ceiling | L12: =SUM(L9:L11) -> 197 | O12: =SUM(O9:O11) -> 286.65 | T12: =SUM(T9:T11) -> 31167.455 | U12: =T12/O12 -> 108.73 | V12: per tile
B13: Material | E13: =SUM(G13/C10) -> 60 | F13: =C11 -> 27 | G13: =C12 -> 36 | U13: =T12/L12 -> 158.21043 | V13: per m2
C14: $/m | J14: SRP
D15: Area | E15: M/No | F15: Total | G15: Waste | J15: List
B16: 28mm furring channel | C16: =J16 -> 3.01 | D16: Change on spacings | E16: =G13/C10 -> 60 | F16: =SUM(C16*E16) -> 180.6 | I16: 28mm Furring | J16: 3.01
B18: Joiner | C18: =J18 -> 1.2 | D18: =C10*3.6 -> 2.16 | E18: =(G13/D18) -> 16.666667 | F18: =SUM(C18*E18) -> 20 | I18: Joiner | J18: 1.2
B19: Locking clip | C19: =J19 -> 0.49 | D19: =C10*F10 -> 0.72 | E19: =(G13/D19) -> 50 | F19: =SUM(C19*E19) -> 24.5 | I19: Locking Clip | J19: 0.49
B20: TCR .75 BMT | C20: =J20 -> 4.04 | D20: =F10 -> 1.2 | E20: =(G13/D20) -> 30 | F20: =SUM(C20*E20) -> 121.2 | I20: TCR 0.75 | J20: 4.04 | L20: 127 or 128 | N20: 125 | O20: 129
B21: Hanging wire | C21: 100 | E21: =ROUNDUP(G13/200,0) -> 1 | F21: =SUM(C21*E21) -> 100
B22: Fixings (to substrate) | C22: 2 | E22: =(G13/F10/G10) -> 25 | F22: =C22*E22 -> 50
B23: Wall Track/Angle | C23: =J23 -> 5.67 | E23: =C11 -> 27 | F23: =C23*E23 -> 153.09 | I23: Wall Track 141 | J23: 5.67
F24: =SUM(F16:F23) -> 649.39 | I24: 40 x 40 x 1.15 Angle | J24: 4.87
B25: Material cost per m2 | C25: =F24/G13 -> 18.038611
B26: Fixings (screws) | C26: 0.015
B27: Unload | C27: 0.03
C28: =SUM(C25:C27) -> 18.083611
B29: waste 5% | C29: =C28*10% -> 1.8083611
B30: Material cost per m2 | C30: =SUM(C28:C29) -> 19.891972
E32: lab rate
E33: 52
B34: Labour per m as per rates | D34: m/hr
B35: Furring channel | C35: =E33/D35 -> 2.08 | D35: 25 | E35: =C35*E13 -> 124.8
B37: TCR | C37: =E33/D37 -> 5.2 | D37: 10 | E37: =E20*C37 -> 156
B38: Fixings | C38: =E33/D38 -> 4.3333333 | D38: 12 | E38: =SUM(C38*E22) -> 108.33333
B39: 40 x 40 | C39: =E33/D39 -> 5.2 | D39: 10 | E39: =C11*C39 -> 140.4
E40: =SUM(E35:E39) -> 529.53333
B41: Labour cost per m2 | C41: =E40/G13 -> 14.709259 | D41: =C41/E33 -> 0.28287037
C42: =SUM(C30+C41) -> 34.601231 | D42: m2 | E42: Total cost per m2
B43: Total cost of ceiling job is | E43: =C42*G13 -> 1245.6443
B45: Cost per m2
B46: Material | C46: =C30 -> 19.891972 | D46: m2
...

Sheet Partitions
B1: =Summary!B1 -> Ceilings Unlimited
B2: =Summary!B2 -> Craigs Investment Partners - Fitout
B3: =Summary!B3 -> Tauranga
B6: =Summary!B5 -> 46043
B9: =Summary!B119 -> Partitions
H11: 50
A12: Item | B12: Description | C12: Qty | D12: Unit | E12: Constant | F12: Constant X Unit = Total HRS | G12: $ Lab per Unit | H12: Total Labour | I12: Materials per Unit | J12: Total Materials | K12: Total Labour & Materials | L12: Total Labour & Materials Per Unit | M12: Total | N12: % Complete | O12: Claim
B14: Level 4:
B16: (P-10) Potters Aluminium Glazing | C16: Refer Potters Trade
B17: (P-10) Bulkhead Structure | C17: 4 | D17: m | E17: =WORKINGS_Partitions!G41 -> 1.977 | F17: =C17*E17 -> 7.908 | G17: =$H$11*E17 -> 98.85 | H17: =F17*$H$11 -> 395.4 | I17: =WORKINGS_Partitions!K41 -> 87.141738 | J17: =C17*I17 -> 348.56695 | K17: =SUM(H17,J17) -> 743.96695 | L17: =K17/C17 -> 185.99174 | M17: =C17*L17 -> 743.96695 | N17: 0 | O17: =M17*N17 -> 0
B18: 13mm Gib Overlay to Above | C18: 4 | D18: m | E18: 0.15 | F18: =C18*E18 -> 0.6 | G18: =$H$11*E18 -> 7.5 | H18: =F18*$H$11 -> 30 | I18: 3.5 | J18: =C18*I18 -> 14 | K18: =SUM(H18,J18) -> 44 | L18: =K18/C18 -> 11 | M18: =C18*L18 -> 44 | N18: 0 | O18: =M18*N18 -> 0
B20: (P-11) Potters Aluminium Glazing | C20: Refer Potters Trade
B21: (P-11) Bulkhead Structure | C21: 23 | D21: m | E21: =WORKINGS_Partitions!G41 -> 1.977 | F21: =C21*E21 -> 45.471 | G21: =$H$11*E21 -> 98.85 | H21: =F21*$H$11 -> 2273.55 | I21: =WORKINGS_Partitions!K41 -> 87.141738 | J21: =C21*I21 -> 2004.26 | K21: =SUM(H21,J21) -> 4277.81 | L21: =K21/C21 -> 185.99174 | M21: =C21*L21 -> 4277.81 | N21: 0 | O21: =M21*N21 -> 0
B22: MDF Capping Strip - 242mm Wide | C22: Not Required, Refer Brevity Design
B23: 13mm Gib Overlay to Above | C23: 23 | D23: m | E23: 0.15 | F23: =C23*E23 -> 3.45 | G23: =$H$11*E23 -> 7.5 | H23: =F23*$H$11 -> 172.5 | I23: 3.5 | J23: =C23*I23 -> 80.5 | K23: =SUM(H23,J23) -> 253 | L23: =K23/C23 -> 11 | M23: =C23*L23 -> 253 | N23: 0 | O23: =M23*N23 -> 0
B25: (P-13) | C25: Refer Potters Trade/Suspended Ceilings | R25: =SUM(C35,C43,C47,C52,C87,C93,C98,C138,C148) -> 82
B27: (P-20A) Bulkhead Structure | C27: 9 | D27: m | E27: =WORKINGS_Partitions!G76 -> 0.72041667 | F27: =C27*E27 -> 6.48375 | G27: =$H$11*E27 -> 36.020833 | H27: =F27*$H$11 -> 324.1875 | I27: =WORKINGS_Partitions!K76 -> 32.029583 | J27: =C27*I27 -> 288.26625 | K27: =SUM(H27,J27) -> 612.45375 | L27: =K27/C27 -> 68.050417 | M27: =C27*L27 -> 612.45375 | N27: 0 | O27: =M27*N27 -> 0 | R27: 92 x 0.75 Stud | S27: 1.15
B28: (P-20A) 92mm x 0.75 Stud @ 400 crs with 1.15 Head Track and 0.70 Base Track with Nogging Track | C28: 34 | D28: m2 | E28: 0.4 | F28: =C28*E28 -> 13.6 | G28: =$H$11*E28 -> 20 | H28: =F28*$H$11 -> 680 | I28: 22.55 | J28: =C28*I28 -> 766.7 | K28: =SUM(H28,J28) -> 1446.7 | L28: =K28/C28 -> 42.55 | M28: =C28*L28 -> 1446.7 | N28: 0 | O28: =M28*N28 -> 0 | P28: 9 | Q28: 3.9 | R28: =(P28/0.4)*Q28 -> 87.75
B30: (P-21S) 92mm x 0.75 Stud @ 400 crs with 1.15 Head Track and 0.70 Base Track | C30: 19 | D30: m2 | E30: 0.44 | F30: =C30*E30 -> 8.36 | G30: =$H$11*E30 -> 22 | H30: =F30*$H$11 -> 418 | I30: 25.23 | J30: =C30*I30 -> 479.37 | K30: =SUM(H30,J30) -> 897.37 | L30: =K30/C30 -> 47.23 | M30: =C30*L30 -> 897.37 | N30: 0 | O30: =M30*N30 -> 0 | P30: 7 | Q30: 2.95 | R30: =(P30/0.4)*Q30 -> 51.625
B32: (P-21) 92mm x 0.75 Stud @ 400 crs with 1.15 Head Track and 0.70 Base Track | C32: 141 | D32: m2 | E32: 0.43 | F32: =C32*E32 -> 60.63 | G32: =$H$11*E32 -> 21.5 | H32: =F32*$H$11 -> 3031.5 | I32: 24.41 | J32: =C32*I32 -> 3441.81 | K32: =SUM(H32,J32) -> 6473.31 | L32: =K32/C32 -> 45.91 | M32: =C32*L32 -> 6473.31 | N32: 0 | O32: =M32*N32 -> 0 | P32: 48 | Q32: 2.95 | R32: =(P32/0.4)*Q32 -> 354
B34: (P-21A) 92mm x 0.75 Stud @ 400 crs with 1.15 Head Track and 0.70 Base Track | C34: 27 | D34: m2 | E34: 0.43 | F34: =C34*E34 -> 11.61 | G34: =$H$11*E34 -> 21.5 | H34: =F34*$H$11 -> 580.5 | I34: 25.02 | J34: =C34*I34 -> 675.54 | K34: =SUM(H34,J34) -> 1256.04 | L34: =K34/C34 -> 46.52 | M34: =C34*L34 -> 1256.04 | N34: 0 | O34: =M34*N34 -> 0 | P34: 9 | Q34: 2.95 | R34: =(P34/0.4)*Q34 -> 66.375
B35: MDF Capping Strip - 241mm Wide | C35: 9 | D35: m | E35: 0.25 | F35: =C35*E35 -> 2.25 | G35: =$H$11*E35 -> 12.5 | H35: =F35*$H$11 -> 112.5 | I35: 23.84 | J35: =C35*I35 -> 214.56 | K35: =SUM(H35,J35) -> 327.06 | L35: =K35/C35 -> 36.34 | M35: =C35*L35 -> 327.06 | N35: 0 | O35: =M35*N35 -> 0
B36: 13mm Gib Overlay to Above | C36: 9 | D36: m | E36: 0.15 | F36: =C36*E36 -> 1.35 | G36: =$H$11*E36 -> 7.5 | H36: =F36*$H$11 -> 67.5 | I36: 3.5 | J36: =C36*I36 -> 31.5 | K36: =SUM(H36,J36) -> 99 | L36: =K36/C36 -> 11 | M36: =C36*L36 -> 99 | N36: 0 | O36: =M36*N36 -> 0
B38: (P-23) 92mm x 0.75 Stud @ 400 crs with 0.70 Head Track and 0.70 Base Track | C38: 84 | D38: m2 | E38: 0.42 | F38: =C38*E38 -> 35.28 | G38: =$H$11*E38 -> 21 | H38: =F38*$H$11 -> 1764 | I38: 22.62 | J38: =C38*I38 -> 1900.08 | K38: =SUM(H38,J38) -> 3664.08 | L38: =K38/C38 -> 43.62 | M38: =C38*L38 -> 3664.08 | N38: 0 | O38: =M38*N38 -> 0 | P38: 29 | Q38: 2.95 | R38: =(P38/0.4)*Q38 -> 213.875
B40: (P-23S) 92mm x 0.75 Stud @ 400 crs with 0.70 Head Track and 0.70 Base Track | C40: 12 | D40: m2 | E40: 0.45 | F40: =C40*E40 -> 5.4 | G40: =$H$11*E40 -> 22.5 | H40: =F40*$H$11 -> 270 | I40: 24.11 | J40: =C40*I40 -> 289.32 | K40: =SUM(H40,J40) -> 559.32 | L40: =K40/C40 -> 46.61 | M40: =C40*L40 -> 559.32 | N40: 0 | O40: =M40*N40 -> 0 | P40: 4 | Q40: 2.95 | R40: =(P40/0.4)*Q40 -> 29.5
B42: (P-23AS) 92mm x 0.75 Stud @ 400 crs with 1.15 Head Track and 0.70 Base Track | C42: 12 | D42: m2 | E42: 0.45 | F42: =C42*E42 -> 5.4 | G42: =$H$11*E42 -> 22.5 | H42: =F42*$H$11 -> 270 | I42: 24.42 | J42: =C42*I42 -> 293.04 | K42: =SUM(H42,J42) -> 563.04 | L42: =K42/C42 -> 46.92 | M42: =C42*L42 -> 563.04 | N42: 0 | O42: =M42*N42 -> 0 | P42: 4 | Q42: 2.9 | R42: =(P42/0.4)*Q42 -> 29
B43: MDF Capping Strip - 228mm Wide | C43: 4 | D43: m | E43: 0.25 | F43: =C43*E43 -> 1 | G43: =$H$11*E43 -> 12.5 | H43: =F43*$H$11 -> 50 | I43: 23.84 | J43: =C43*I43 -> 95.36 | K43: =SUM(H43,J43) -> 145.36 | L43: =K43/C43 -> 36.34 | M43: =C43*L43 -> 145.36 | N43: 0 | O43: =M43*N43 -> 0
B44: 13mm Gib Overlay to Above | C44: 4 | D44: m | E44: 0.15 | F44: =C44*E44 -> 0.6 | G44: =$H$11*E44 -> 7.5 | H44: =F44*$H$11 -> 30 | I44: 3.5 | J44: =C44*I44 -> 14 | K44: =SUM(H44,J44) -> 44 | L44: =K44/C44 -> 11 | M44: =C44*L44 -> 44 | N44: 0 | O44: =M44*N44 -> 0
B46: (P-23A) 92mm x 0.75 Stud @ 400 crs with 1.15 Head Track and 0.70 Base Track | C46: 74 | D46: m2 | E46: 0.43 | F46: =C46*E46 -> 31.82 | G46: =$H$11*E46 -> 21.5 | H46: =F46*$H$11 -> 1591 | I46: 23 | J46: =C46*I46 -> 1702 | K46: =SUM(H46,J46) -> 3293 | L46: =K46/C46 -> 44.5 | M46: =C46*L46 -> 3293 | N46: 0 | O46: =M46*N46 -> 0 | P46: 25 | Q46: 2.9 | R46: =(P46/0.4)*Q46 -> 181.25
B47: MDF Capping Strip - 228mm Wide | C47: 25 | D47: m | E47: 0.25 | F47: =C47*E47 -> 6.25 | G47: =$H$11*E47 -> 12.5 | H47: =F47*$H$11 -> 312.5 | I47: 23.84 | J47: =C47*I47 -> 596 | K47: =SUM(H47,J47) -> 908.5 | L47: =K47/C47 -> 36.34 | M47: =C47*L47 -> 908.5 | N47: 0 | O47: =M47*N47 -> 0
B48: 13mm Gib Overlay to Above | C48: 25 | D48: m | E48: 0.15 | F48: =C48*E48 -> 3.75 | G48: =$H$11*E48 -> 7.5 | H48: =F48*$H$11 -> 187.5 | I48: 3.5 | J48: =C48*I48 -> 87.5 | K48: =SUM(H48,J48) -> 275 | L48: =K48/C48 -> 11 | M48: =C48*L48 -> 275 | N48: 0 | O48: =M48*N48 -> 0
B50: (P-23B) Bulkhead Structure | C50: 11 | D50: m | E50: =WORKINGS_Partitions!G89 -> 1.005 | F50: =C50*E50 -> 11.055 | G50: =$H$11*E50 -> 50.25 | H50: =F50*$H$11 -> 552.75 | I50: =WORKINGS_Partitions!K89 -> 32.238942 | J50: =C50*I50 -> 354.62836 | K50: =SUM(H50,J50) -> 907.37836 | L50: =K50/C50 -> 82.488942 | M50: =C50*L50 -> 907.37836 | N50: 0 | O50: =M50*N50 -> 0
B51: (P-23B) 92mm x 0.75 Stud @ 400 crs with 1.15 Head Track and 0.70 Base Track | C51: 31 | D51: m2 | E51: 0.44 | F51: =C51*E51 -> 13.64 | G51: =$H$11*E51 -> 22 | H51: =F51*$H$11 -> 682 | I51: 25.25 | J51: =C51*I51 -> 782.75 | K51: =SUM(H51,J51) -> 1464.75 | L51: =K51/C51 -> 47.25 | M51: =C51*L51 -> 1464.75 | N51: 0 | O51: =M51*N51 -> 0 | P51: 11 | Q51: 2.9 | R51: =(P51/0.4)*Q51 -> 79.75
B52: MDF Capping Strip - 228mm Wide | C52: 11 | D52: m | E52: 0.25 | F52: =C52*E52 -> 2.75 | G52: =$H$11*E52 -> 12.5 | H52: =F52*$H$11 -> 137.5 | I52: 23.84 | J52: =C52*I52 -> 262.24 | K52: =SUM(H52,J52) -> 399.74 | L52: =K52/C52 -> 36.34 | M52: =C52*L52 -> 399.74 | N52: 0 | O52: =M52*N52 -> 0
B53: 13mm Gib Overlay to Above | C53: 11 | D53: m | E53: 0.15 | F53: =C53*E53 -> 1.65 | G53: =$H$11*E53 -> 7.5 | H53: =F53*$H$11 -> 82.5 | I53: 3.5 | J53: =C53*I53 -> 38.5 | K53: =SUM(H53,J53) -> 121 | L53: =K53/C53 -> 11 | M53: =C53*L53 -> 121 | N53: 0 | O53: =M53*N53 -> 0
B55: Trackloks - Part Height Walls | C55: 43 | D55: no | E55: 0.75 | F55: =C55*E55 -> 32.25 | G55: =$H$11*E55 -> 37.5 | H55: =F55*$H$11 -> 1612.5 | I55: 85.17 | J55: =C55*I55 -> 3662.31 | K55: =SUM(H55,J55) -> 5274.81 | L55: =K55/C55 -> 122.67 | M55: =C55*L55 -> 5274.81 | N55: 0 | O55: =M55*N55 -> 0
B57: Trackloks - TB-02 | C57: Refer Featurecraft Trade
B59: Bridge to Confloor | C59: =SUM(P28) -> 9 | D59: m | E59: 0.25 | F59: =C59*E59 -> 2.25 | G59: =$H$11*E59 -> 12.5 | H59: =F59*$H$11 -> 112.5 | I59: 15 | J59: =C59*I59 -> 135 | K59: =SUM(H59,J59) -> 247.5 | L59: =K59/C59 -> 27.5 | M59: =C59*L59 -> 247.5 | N59: 0 | O59: =M59*N59 -> 0
B60: EV Stud to Corners/Intersections | C60: 492 | D60: m | E60: 0.09 | F60: =C60*E60 -> 44.28 | G60: =$H$11*E60 -> 4.5 | H60: =F60*$H$11 -> 2214 | I60: 5.61 | J60: =C60*I60 -> 2760.12 | K60: =SUM(H60,J60) -> 4974.12 | L60: =K60/C60 -> 10.11 | M60: =C60*L60 -> 4974.12 | N60: 0 | O60: =M60*N60 -> 0
B61: Plywood Support/Nogging - TV's | C61: 7 | D61: item | E61: 1.5 | F61: =C61*E61 -> 10.5 | G61: =$H$11*E61 -> 75 | H61: =F61*$H$11 -> 525 | I61: 139 | J61: =C61*I61 -> 973 | K61: =SUM(H61,J61) -> 1498 | L61: =K61/C61 -> 214 | M61: =C61*L61 -> 1498 | N61: 0 | O61: =M61*N61 -> 0
...

Sheet Partitions SPEC Rates
B1: =Summary!B1 -> Ceilings Unlimited
B2: =Summary!B2 -> Craigs Investment Partners - Fitout
B3: =Summary!B3 -> Tauranga
B6: =Summary!B5 -> 46043
B9: =Summary!B119 -> Partitions
H11: 50
A12: Item | B12: Description | C12: Qty | D12: Unit | E12: Constant | F12: Constant X Unit = Total HRS | G12: $ Lab per Unit | H12: Total Labour | I12: Materials per Unit | J12: Total Materials | K12: Total Labour & Materials | L12: Total Labour & Materials Per Unit | M12: Total | N12: % Complete | O12: Claim
B14: Level 4:
B16: (P-10) Potters Aluminium Glazing | C16: Refer Potters Trade
B17: (P-10) Bulkhead Structure | C17: 4 | D17: m | E17: ='WORKINGS_Partitions SPEC Rates'!G41 -> 1.977 | F17: =C17*E17 -> 7.908 | G17: =$H$11*E17 -> 98.85 | H17: =F17*$H$11 -> 395.4 | I17: ='WORKINGS_Partitions SPEC Rates'!K41 -> 68.917518 | J17: =C17*I17 -> 275.67007 | K17: =SUM(H17,J17) -> 671.07007 | L17: =K17/C17 -> 167.76752 | M17: =C17*L17 -> 671.07007 | N17: 0 | O17: =M17*N17 -> 0
B18: 13mm Gib Overlay to Above | C18: 4 | D18: m | E18: 0.15 | F18: =C18*E18 -> 0.6 | G18: =$H$11*E18 -> 7.5 | H18: =F18*$H$11 -> 30 | I18: 3.5 | J18: =C18*I18 -> 14 | K18: =SUM(H18,J18) -> 44 | L18: =K18/C18 -> 11 | M18: =C18*L18 -> 44 | N18: 0 | O18: =M18*N18 -> 0
B20: (P-11) Potters Aluminium Glazing | C20: Refer Potters Trade
B21: (P-11) Bulkhead Structure | C21: 23 | D21: m | E21: ='WORKINGS_Partitions SPEC Rates'!G41 -> 1.977 | F21: =C21*E21 -> 45.471 | G21: =$H$11*E21 -> 98.85 | H21: =F21*$H$11 -> 2273.55 | I21: ='WORKINGS_Partitions SPEC Rates'!K41 -> 68.917518 | J21: =C21*I21 -> 1585.1029 | K21: =SUM(H21,J21) -> 3858.6529 | L21: =K21/C21 -> 167.76752 | M21: =C21*L21 -> 3858.6529 | N21: 0 | O21: =M21*N21 -> 0
B22: MDF Capping Strip - 242mm Wide | C22: Not Required, Refer Brevity Design
B23: 13mm Gib Overlay to Above | C23: 23 | D23: m | E23: 0.15 | F23: =C23*E23 -> 3.45 | G23: =$H$11*E23 -> 7.5 | H23: =F23*$H$11 -> 172.5 | I23: 3.5 | J23: =C23*I23 -> 80.5 | K23: =SUM(H23,J23) -> 253 | L23: =K23/C23 -> 11 | M23: =C23*L23 -> 253 | N23: 0 | O23: =M23*N23 -> 0
B25: (P-13) | C25: Refer Potters Trade/Suspended Ceilings | R25: =SUM(C36,C44,C48,C53,C88,C94,C99,C137,C143) -> 82
B27: (P-20A) Bulkhead Structure | C27: 9 | D27: m | E27: ='WORKINGS_Partitions SPEC Rates'!G76 -> 0.72041667 | F27: =C27*E27 -> 6.48375 | G27: =$H$11*E27 -> 36.020833 | H27: =F27*$H$11 -> 324.1875 | I27: ='WORKINGS_Partitions SPEC Rates'!K76 -> 23.380602 | J27: =C27*I27 -> 210.42542 | K27: =SUM(H27,J27) -> 534.61292 | L27: =K27/C27 -> 59.401435 | M27: =C27*L27 -> 534.61292 | N27: 0 | O27: =M27*N27 -> 0 | R27: 92 x 0.75 Stud | S27: 1.15
B28: (P-20A) 92mm x 0.75 Stud @ 400 crs with 1.15 Head Track and 0.70 Base Track with Nogging Track | C28: 34 | D28: m2 | E28: 0.4 | F28: =C28*E28 -> 13.6 | G28: =$H$11*E28 -> 20 | H28: =F28*$H$11 -> 680 | I28: 17.74 | J28: =C28*I28 -> 603.16 | K28: =SUM(H28,J28) -> 1283.16 | L28: =K28/C28 -> 37.74 | M28: =C28*L28 -> 1283.16 | N28: 0 | O28: =M28*N28 -> 0 | P28: 9 | Q28: 3.9 | R28: =(P28/0.4)*Q28 -> 87.75
B31: (P-21S) 92mm x 0.75 Stud @ 400 crs with 1.15 Head Track and 0.70 Base Track | C31: 19 | D31: m2 | E31: 0.44 | F31: =C31*E31 -> 8.36 | G31: =$H$11*E31 -> 22 | H31: =F31*$H$11 -> 418 | I31: 19.7 | J31: =C31*I31 -> 374.3 | K31: =SUM(H31,J31) -> 792.3 | L31: =K31/C31 -> 41.7 | M31: =C31*L31 -> 792.3 | N31: 0 | O31: =M31*N31 -> 0 | P31: 7 | Q31: 2.95 | R31: =(P31/0.4)*Q31 -> 51.625
B33: (P-21) 92mm x 0.75 Stud @ 400 crs with 1.15 Head Track and 0.70 Base Track | C33: 141 | D33: m2 | E33: 0.43 | F33: =C33*E33 -> 60.63 | G33: =$H$11*E33 -> 21.5 | H33: =F33*$H$11 -> 3031.5 | I33: 19 | J33: =C33*I33 -> 2679 | K33: =SUM(H33,J33) -> 5710.5 | L33: =K33/C33 -> 40.5 | M33: =C33*L33 -> 5710.5 | N33: 0 | O33: =M33*N33 -> 0 | P33: 48 | Q33: 2.95 | R33: =(P33/0.4)*Q33 -> 354
B35: (P-21A) 92mm x 0.75 Stud @ 400 crs with 1.15 Head Track and 0.70 Base Track | C35: 27 | D35: m2 | E35: 0.43 | F35: =C35*E35 -> 11.61 | G35: =$H$11*E35 -> 21.5 | H35: =F35*$H$11 -> 580.5 | I35: 19.52 | J35: =C35*I35 -> 527.04 | K35: =SUM(H35,J35) -> 1107.54 | L35: =K35/C35 -> 41.02 | M35: =C35*L35 -> 1107.54 | N35: 0 | O35: =M35*N35 -> 0 | P35: 9 | Q35: 2.95 | R35: =(P35/0.4)*Q35 -> 66.375
B36: MDF Capping Strip - 241mm Wide | C36: 9 | D36: m | E36: 0.25 | F36: =C36*E36 -> 2.25 | G36: =$H$11*E36 -> 12.5 | H36: =F36*$H$11 -> 112.5 | I36: 23.84 | J36: =C36*I36 -> 214.56 | K36: =SUM(H36,J36) -> 327.06 | L36: =K36/C36 -> 36.34 | M36: =C36*L36 -> 327.06 | N36: 0 | O36: =M36*N36 -> 0
B37: 13mm Gib Overlay to Above | C37: 9 | D37: m | E37: 0.15 | F37: =C37*E37 -> 1.35 | G37: =$H$11*E37 -> 7.5 | H37: =F37*$H$11 -> 67.5 | I37: 3.5 | J37: =C37*I37 -> 31.5 | K37: =SUM(H37,J37) -> 99 | L37: =K37/C37 -> 11 | M37: =C37*L37 -> 99 | N37: 0 | O37: =M37*N37 -> 0
B39: (P-23) 92mm x 0.75 Stud @ 400 crs with 0.70 Head Track and 0.70 Base Track | C39: 84 | D39: m2 | E39: 0.42 | F39: =C39*E39 -> 35.28 | G39: =$H$11*E39 -> 21 | H39: =F39*$H$11 -> 1764 | I39: 19.08 | J39: =C39*I39 -> 1602.72 | K39: =SUM(H39,J39) -> 3366.72 | L39: =K39/C39 -> 40.08 | M39: =C39*L39 -> 3366.72 | N39: 0 | O39: =M39*N39 -> 0 | P39: 29 | Q39: 2.95 | R39: =(P39/0.4)*Q39 -> 213.875
B41: (P-23S) 92mm x 0.75 Stud @ 400 crs with 0.70 Head Track and 0.70 Base Track | C41: 12 | D41: m2 | E41: 0.45 | F41: =C41*E41 -> 5.4 | G41: =$H$11*E41 -> 22.5 | H41: =F41*$H$11 -> 270 | I41: 19.89 | J41: =C41*I41 -> 238.68 | K41: =SUM(H41,J41) -> 508.68 | L41: =K41/C41 -> 42.39 | M41: =C41*L41 -> 508.68 | N41: 0 | O41: =M41*N41 -> 0 | P41: 4 | Q41: 2.95 | R41: =(P41/0.4)*Q41 -> 29.5
B43: (P-23AS) 92mm x 0.75 Stud @ 400 crs with 1.15 Head Track and 0.70 Base Track | C43: 12 | D43: m2 | E43: 0.45 | F43: =C43*E43 -> 5.4 | G43: =$H$11*E43 -> 22.5 | H43: =F43*$H$11 -> 270 | I43: 20.59 | J43: =C43*I43 -> 247.08 | K43: =SUM(H43,J43) -> 517.08 | L43: =K43/C43 -> 43.09 | M43: =C43*L43 -> 517.08 | N43: 0 | O43: =M43*N43 -> 0 | P43: 4 | Q43: 2.9 | R43: =(P43/0.4)*Q43 -> 29
B44: MDF Capping Strip - 228mm Wide | C44: 4 | D44: m | E44: 0.25 | F44: =C44*E44 -> 1 | G44: =$H$11*E44 -> 12.5 | H44: =F44*$H$11 -> 50 | I44: 23.84 | J44: =C44*I44 -> 95.36 | K44: =SUM(H44,J44) -> 145.36 | L44: =K44/C44 -> 36.34 | M44: =C44*L44 -> 145.36 | N44: 0 | O44: =M44*N44 -> 0
B45: 13mm Gib Overlay to Above | C45: 4 | D45: m | E45: 0.15 | F45: =C45*E45 -> 0.6 | G45: =$H$11*E45 -> 7.5 | H45: =F45*$H$11 -> 30 | I45: 3.5 | J45: =C45*I45 -> 14 | K45: =SUM(H45,J45) -> 44 | L45: =K45/C45 -> 11 | M45: =C45*L45 -> 44 | N45: 0 | O45: =M45*N45 -> 0
B47: (P-23A) 92mm x 0.75 Stud @ 400 crs with 1.15 Head Track and 0.70 Base Track | C47: 74 | D47: m2 | E47: 0.43 | F47: =C47*E47 -> 31.82 | G47: =$H$11*E47 -> 21.5 | H47: =F47*$H$11 -> 1591 | I47: 19.38 | J47: =C47*I47 -> 1434.12 | K47: =SUM(H47,J47) -> 3025.12 | L47: =K47/C47 -> 40.88 | M47: =C47*L47 -> 3025.12 | N47: 0 | O47: =M47*N47 -> 0 | P47: 25 | Q47: 2.9 | R47: =(P47/0.4)*Q47 -> 181.25
B48: MDF Capping Strip - 228mm Wide | C48: 25 | D48: m | E48: 0.25 | F48: =C48*E48 -> 6.25 | G48: =$H$11*E48 -> 12.5 | H48: =F48*$H$11 -> 312.5 | I48: 23.84 | J48: =C48*I48 -> 596 | K48: =SUM(H48,J48) -> 908.5 | L48: =K48/C48 -> 36.34 | M48: =C48*L48 -> 908.5 | N48: 0 | O48: =M48*N48 -> 0
B49: 13mm Gib Overlay to Above | C49: 25 | D49: m | E49: 0.15 | F49: =C49*E49 -> 3.75 | G49: =$H$11*E49 -> 7.5 | H49: =F49*$H$11 -> 187.5 | I49: 3.5 | J49: =C49*I49 -> 87.5 | K49: =SUM(H49,J49) -> 275 | L49: =K49/C49 -> 11 | M49: =C49*L49 -> 275 | N49: 0 | O49: =M49*N49 -> 0
B51: (P-23B) Bulkhead Structure | C51: 11 | D51: m | E51: =WORKINGS_Partitions!G89 -> 1.005 | F51: =C51*E51 -> 11.055 | G51: =$H$11*E51 -> 50.25 | H51: =F51*$H$11 -> 552.75 | I51: ='WORKINGS_Partitions SPEC Rates'!K89 -> 26.385192 | J51: =C51*I51 -> 290.23711 | K51: =SUM(H51,J51) -> 842.98711 | L51: =K51/C51 -> 76.635192 | M51: =C51*L51 -> 842.98711 | N51: 0 | O51: =M51*N51 -> 0
B52: (P-23B) 92mm x 0.75 Stud @ 400 crs with 1.15 Head Track and 0.70 Base Track | C52: 31 | D52: m2 | E52: 0.44 | F52: =C52*E52 -> 13.64 | G52: =$H$11*E52 -> 22 | H52: =F52*$H$11 -> 682 | I52: 19.67 | J52: =C52*I52 -> 609.77 | K52: =SUM(H52,J52) -> 1291.77 | L52: =K52/C52 -> 41.67 | M52: =C52*L52 -> 1291.77 | N52: 0 | O52: =M52*N52 -> 0 | P52: 11 | Q52: 2.9 | R52: =(P52/0.4)*Q52 -> 79.75
B53: MDF Capping Strip - 228mm Wide | C53: 11 | D53: m | E53: 0.25 | F53: =C53*E53 -> 2.75 | G53: =$H$11*E53 -> 12.5 | H53: =F53*$H$11 -> 137.5 | I53: 23.84 | J53: =C53*I53 -> 262.24 | K53: =SUM(H53,J53) -> 399.74 | L53: =K53/C53 -> 36.34 | M53: =C53*L53 -> 399.74 | N53: 0 | O53: =M53*N53 -> 0
B54: 13mm Gib Overlay to Above | C54: 11 | D54: m | E54: 0.15 | F54: =C54*E54 -> 1.65 | G54: =$H$11*E54 -> 7.5 | H54: =F54*$H$11 -> 82.5 | I54: 3.5 | J54: =C54*I54 -> 38.5 | K54: =SUM(H54,J54) -> 121 | L54: =K54/C54 -> 11 | M54: =C54*L54 -> 121 | N54: 0 | O54: =M54*N54 -> 0
B56: Trackloks - Part Height Walls | C56: 43 | D56: no | E56: 0.75 | F56: =C56*E56 -> 32.25 | G56: =$H$11*E56 -> 37.5 | H56: =F56*$H$11 -> 1612.5 | I56: 82.5 | J56: =C56*I56 -> 3547.5 | K56: =SUM(H56,J56) -> 5160 | L56: =K56/C56 -> 120 | M56: =C56*L56 -> 5160 | N56: 0 | O56: =M56*N56 -> 0
B58: Trackloks - TB-02 | C58: Refer Featurecraft Trade
B60: Bridge to Confloor | C60: =SUM(P28) -> 9 | D60: m | E60: 0.25 | F60: =C60*E60 -> 2.25 | G60: =$H$11*E60 -> 12.5 | H60: =F60*$H$11 -> 112.5 | I60: 15 | J60: =C60*I60 -> 135 | K60: =SUM(H60,J60) -> 247.5 | L60: =K60/C60 -> 27.5 | M60: =C60*L60 -> 247.5 | N60: 0 | O60: =M60*N60 -> 0
B61: EV Stud to Corners/Intersections | C61: 492 | D61: m | E61: 0.09 | F61: =C61*E61 -> 44.28 | G61: =$H$11*E61 -> 4.5 | H61: =F61*$H$11 -> 2214 | I61: 5.61 | J61: =C61*I61 -> 2760.12 | K61: =SUM(H61,J61) -> 4974.12 | L61: =K61/C61 -> 10.11 | M61: =C61*L61 -> 4974.12 | N61: 0 | O61: =M61*N61 -> 0
B62: Plywood Support/Nogging - TV's | C62: 7 | D62: item | E62: 1.5 | F62: =C62*E62 -> 10.5 | G62: =$H$11*E62 -> 75 | H62: =F62*$H$11 -> 525 | I62: 139 | J62: =C62*I62 -> 973 | K62: =SUM(H62,J62) -> 1498 | L62: =K62/C62 -> 214 | M62: =C62*L62 -> 1498 | N62: 0 | O62: =M62*N62 -> 0
...

Sheet WORKINGS_Partitions SPEC Rates
R2: Rondo | T2: SRP
R3: List | S3: Job Special | T3: List | U3: Job Special
O4: 92mm x 1.15 Head Track | T4: 10.17
C5: Plywood Nogging | D5: 12mm Plywood | E5: 1 | F5: Sheet | G5: 75 | H5: =E5*G5 -> 75 | O5: 92mm x 1.15 DHT | P5: 375 l/m | T5: 11.4 | U5: 6.45
D6: Nogging Brackets | E6: 14 | F6: No | G6: 4.34 | H6: =E6*G6 -> 60.76 | O6: 92mm x 0.75 DHT | T6: 6.13 | U6: 4.31
D7: Fixings | E7: 1 | F7: item | G7: 2.5 | H7: =E7*G7 -> 2.5 | O7: 92mm x 0.75 Stud | P7: 4500 l/m | T7: 5.23 | U7: 3.71
H8: =SUM(H5:H7) -> 138.26 | O8: 92mm x 0.70 Base Track | P8: 375 l/m | T8: 5.23 | U8: 3.71
O9: 92mm Nogging Track | T9: 8.48
O10: 64mm x 0.75 DHT | T10: 5.67 | U10: 3.71
O11: 64mm Nogging Track | T11: 6.5 | U11: 4.29
O12: 64mm x 0.55 Head Track | T12: 2.89
O13: 64mm x 0.70 Stud | T13: 4.71 | U13: 3.21
O14: BC90 Brackets | T14: 4.85 | U14: 4.85
O15: BC45 Brackets | T15: 4.85 | U15: 4.85
O16: 90 x 45 SG8 | Q16: 3.8
O17: Hilti Hus 4-H 70mm | Q17: 1.7
C20: P10 or P11 - Bulkhead Structure Make Up | D20: 1 | E20: LENGTH | F20: 1 | G20: HEIGHT | H20: =Partitions!H11 -> 50
P21: Rate | Q21: Wastage | S21: Loadin
Q22: 1.05
C23: 92 x 1.15 Head Track | D23: =D20 -> 1 | E23: m | F23: 0.15 | G23: =D23*F23 -> 0.15 | H23: =$H$20*F23 -> 7.5 | I23: =G23*$H$20 -> 7.5 | J23: =T23 -> 7.0225 | K23: =D23*J23 -> 7.0225 | L23: =SUM(I23,K23) -> 14.5225 | M23: =L23/D23 -> 14.5225 | N23: =D23*M23 -> 14.5225 | P23: =U5 -> 6.45 | Q23: =P23*$Q$22 -> 6.7725 | R23: =Q23 -> 6.7725 | S23: 0.25 | T23: =SUM(R23:S23) -> 7.0225
C24: Hilti Hus 4-H 70mm Fixing to above | D24: =D23/0.6 -> 1.6666667 | E24: no | F24: 0.1 | G24: =D24*F24 -> 0.16666667 | H24: =$H$20*F24 -> 5 | I24: =G24*$H$20 -> 8.3333333 | J24: =Q17 -> 1.7 | K24: =D24*J24 -> 2.8333333 | L24: =SUM(I24,K24) -> 11.166667 | M24: =L24/D24 -> 6.7 | N24: =D24*M24 -> 11.166667 | Q24: =P24*$Q$22 -> 0 | R24: =Q24 -> 0 | T24: =SUM(R24:S24) -> 0
C25: 92 x 0.75 Dropper Stud | D25: =(D20/0.6)*F20 -> 1.6666667 | E25: m | F25: 0.1 | G25: =D25*F25 -> 0.16666667 | H25: =$H$20*F25 -> 5 | I25: =G25*$H$20 -> 8.3333333 | J25: =T25 -> 4.1455 | K25: =D25*J25 -> 6.9091667 | L25: =SUM(I25,K25) -> 15.2425 | M25: =L25/D25 -> 9.1455 | N25: =D25*M25 -> 15.2425 | P25: =U7 -> 3.71 | Q25: =P25*$Q$22 -> 3.8955 | R25: =Q25 -> 3.8955 | S25: 0.25 | T25: =SUM(R25:S25) -> 4.1455
C27: 64mm x 0.55 Head Track | D27: =D20 -> 1 | E27: m | F27: 0.15 | G27: =D27*F27 -> 0.15 | H27: =$H$20*F27 -> 7.5 | I27: =G27*$H$20 -> 7.5 | J27: =T27 -> 3.2845 | K27: =D27*J27 -> 3.2845 | L27: =SUM(I27,K27) -> 10.7845 | M27: =L27/D27 -> 10.7845 | N27: =D27*M27 -> 10.7845 | P27: =T12 -> 2.89 | Q27: =P27*$Q$22 -> 3.0345 | R27: =Q27 -> 3.0345 | S27: 0.25 | T27: =SUM(R27:S27) -> 3.2845
C28: Hilti Hus 4-H 70mm Fixing to above | D28: =D27/0.6 -> 1.6666667 | E28: no | F28: 0.1 | G28: =D28*F28 -> 0.16666667 | H28: =$H$20*F28 -> 5 | I28: =G28*$H$20 -> 8.3333333 | J28: =Q17 -> 1.7 | K28: =D28*J28 -> 2.8333333 | L28: =SUM(I28,K28) -> 11.166667 | M28: =L28/D28 -> 6.7 | N28: =D28*M28 -> 11.166667 | Q28: =P28*$Q$22 -> 0 | R28: =Q28 -> 0 | T28: =SUM(R28:S28) -> 0
C29: 64 x 0.70 Dropper Stud | D29: =(D20/0.6)*F20 -> 1.6666667 | E29: m | F29: 0.1 | G29: =D29*F29 -> 0.16666667 | H29: =$H$20*F29 -> 5 | I29: =G29*$H$20 -> 8.3333333 | J29: =T29 -> 3.6205 | K29: =D29*J29 -> 6.0341667 | L29: =SUM(I29,K29) -> 14.3675 | M29: =L29/D29 -> 8.6205 | N29: =D29*M29 -> 14.3675 | P29: =U13 -> 3.21 | Q29: =P29*$Q$22 -> 3.3705 | R29: =Q29 -> 3.3705 | S29: 0.25 | T29: =SUM(R29:S29) -> 3.6205
C31: 92 x 0.75 Bridge Stud | D31: =(D20/0.6)*0.242 -> 0.40333333 | E31: m | F31: 0.1 | G31: =D31*F31 -> 0.040333333 | H31: =$H$20*F31 -> 5 | I31: =G31*$H$20 -> 2.0166667 | J31: =T31 -> 4.1455 | K31: =D31*J31 -> 1.6720183 | L31: =SUM(I31,K31) -> 3.688685 | M31: =L31/D31 -> 9.1455 | N31: =D31*M31 -> 3.688685 | P31: =U7 -> 3.71 | Q31: =P31*$Q$22 -> 3.8955 | R31: =Q31 -> 3.8955 | S31: 0.25 | T31: =SUM(R31:S31) -> 4.1455
C32: BC90 Brackets | D32: =(D20/0.6)*2 -> 3.3333333 | E32: no | F32: 0.15 | G32: =D32*F32 -> 0.5 | H32: =$H$20*F32 -> 7.5 | I32: =G32*$H$20 -> 25 | J32: =T32 -> 5.0925 | K32: =D32*J32 -> 16.975 | L32: =SUM(I32,K32) -> 41.975 | M32: =L32/D32 -> 12.5925 | N32: =D32*M32 -> 41.975 | P32: =T14 -> 4.85 | Q32: =P32*$Q$22 -> 5.0925 | R32: =Q32 -> 5.0925 | T32: =SUM(R32:S32) -> 5.0925
C34: 92 x 0.70 Boxed Stud Lintel | D34: =D20 -> 1 | E34: m | F34: 0.2 | G34: =D34*F34 -> 0.2 | H34: =$H$20*F34 -> 10 | I34: =G34*$H$20 -> 10 | J34: =T34*2 -> 8.791 | K34: =D34*J34 -> 8.791 | L34: =SUM(I34,K34) -> 18.791 | M34: =L34/D34 -> 18.791 | N34: =D34*M34 -> 18.791 | O34: Double Rate | P34: =U7 -> 3.71 | Q34: =P34*$Q$22 -> 3.8955 | R34: =Q34 -> 3.8955 | S34: 0.5 | T34: =SUM(R34:S34) -> 4.3955
C35: 92 x 1.15 DHT | D35: =D20 -> 1 | E35: m | F35: 0.1 | G35: =D35*F35 -> 0.1 | H35: =$H$20*F35 -> 5 | I35: =G35*$H$20 -> 5 | J35: =T35 -> 7.0225 | K35: =D35*J35 -> 7.0225 | L35: =SUM(I35,K35) -> 12.0225 | M35: =L35/D35 -> 12.0225 | N35: =D35*M35 -> 12.0225 | P35: =U5 -> 6.45 | Q35: =P35*$Q$22 -> 6.7725 | R35: =Q35 -> 6.7725 | S35: 0.25 | T35: =SUM(R35:S35) -> 7.0225
C37: 90 x 45 SG8 Timber Support | D37: =D20 -> 1 | E37: m | F37: 0.17 | G37: =D37*F37 -> 0.17 | H37: =$H$20*F37 -> 8.5 | I37: =G37*$H$20 -> 8.5 | J37: =T37 -> 4.24 | K37: =D37*J37 -> 4.24 | L37: =SUM(I37,K37) -> 12.74 | M37: =L37/D37 -> 12.74 | N37: =D37*M37 -> 12.74 | P37: =Q16 -> 3.8 | Q37: =P37*$Q$22 -> 3.99 | R37: =Q37 -> 3.99 | S37: 0.25 | T37: =SUM(R37:S37) -> 4.24
C39: Teks | D39: =(D20/0.6)*30 -> 50 | E39: no | F39: 0 | G39: =D39*F39 -> 0 | H39: =$H$20*F39 -> 0 | I39: =G39*$H$20 -> 0 | J39: 0.026 | K39: =D39*J39 -> 1.3 | L39: =SUM(I39,K39) -> 1.3 | M39: =L39/D39 -> 0.026 | N39: =D39*M39 -> 1.3 | Q39: =P39*$Q$22 -> 0 | R39: =Q39 -> 0 | T39: =SUM(R39:S39) -> 0
G41: =SUM(G23:G40) -> 1.977 | I41: =SUM(I23:I40) -> 98.85 | K41: =SUM(K23:K40) -> 68.917518 | N41: =SUM(N23:N40) -> 167.76752
C43: P12 - Bulkhead Structure Make Up | D43: 1 | E43: LENGTH | F43: 1 | G43: HEIGHT | H43: =Partitions!H11 -> 50
P44: Rate | Q44: Wastage | S44: Loadin
Q45: 1.05
C46: 92 x 1.15 Head Track | D46: =D43 -> 1 | E46: m | F46: 0.15 | G46: =D46*F46 -> 0.15 | H46: =$H$43*F46 -> 7.5 | I46: =G46*$H$20 -> 7.5 | J46: =T46 -> 7.0225 | K46: =D46*J46 -> 7.0225 | L46: =SUM(I46,K46) -> 14.5225 | M46: =L46/D46 -> 14.5225 | N46: =D46*M46 -> 14.5225 | P46: =U5 -> 6.45 | Q46: =P46*$Q$22 -> 6.7725 | R46: =Q46 -> 6.7725 | S46: 0.25 | T46: =SUM(R46:S46) -> 7.0225
C47: Hilti Hus 4-H 70mm Fixing to above | D47: =D43/0.6 -> 1.6666667 | E47: no | F47: 0.1 | G47: =D47*F47 -> 0.16666667 | H47: =$H$43*F47 -> 5 | I47: =G47*$H$20 -> 8.3333333 | J47: =Q17 -> 1.7 | K47: =D47*J47 -> 2.8333333 | L47: =SUM(I47,K47) -> 11.166667 | M47: =L47/D47 -> 6.7 | N47: =D47*M47 -> 11.166667 | Q47: =P47*$Q$22 -> 0 | R47: =Q47 -> 0 | T47: =SUM(R47:S47) -> 0
C48: 92 x 0.75 Dropper Stud | D48: =(D43/0.6)*F43 -> 1.6666667 | E48: m | F48: 0.1 | G48: =D48*F48 -> 0.16666667 | H48: =$H$43*F48 -> 5 | I48: =G48*$H$20 -> 8.3333333 | J48: =T48 -> 4.1455 | K48: =D48*J48 -> 6.9091667 | L48: =SUM(I48,K48) -> 15.2425 | M48: =L48/D48 -> 9.1455 | N48: =D48*M48 -> 15.2425 | P48: =U7 -> 3.71 | Q48: =P48*$Q$22 -> 3.8955 | R48: =Q48 -> 3.8955 | S48: 0.25 | T48: =SUM(R48:S48) -> 4.1455
C50: BC90 Brackets | D50: =D43/0.6 -> 1.6666667 | E50: no | F50: 0.07 | G50: =D50*F50 -> 0.11666667 | H50: =$H$43*F50 -> 3.5 | I50: =G50*$H$20 -> 5.8333333 | J50: =T50 -> 5.0925 | K50: =D50*J50 -> 8.4875 | L50: =SUM(I50,K50) -> 14.320833 | M50: =L50/D50 -> 8.5925 | N50: =D50*M50 -> 14.320833 | P50: =T14 -> 4.85 | Q50: =P50*$Q$22 -> 5.0925 | R50: =Q50 -> 5.0925 | T50: =SUM(R50:S50) -> 5.0925
C52: BC45 Brackets | D52: =(D43/1.8)*2 -> 1.1111111 | E52: no | F52: 0.07 | G52: =D52*F52 -> 0.077777778 | H52: =$H$43*F52 -> 3.5 | I52: =G52*$H$20 -> 3.8888889 | J52: =T52 -> 5.0925 | K52: =D52*J52 -> 5.6583333 | L52: =SUM(I52,K52) -> 9.5472222 | M52: =L52/D52 -> 8.5925 | N52: =D52*M52 -> 9.5472222 | P52: =T15 -> 4.85 | Q52: =P52*$Q$22 -> 5.0925 | R52: =Q52 -> 5.0925 | T52: =SUM(R52:S52) -> 5.0925
...

Sheet WORKINGS_Partitions
R2: Rondo | T2: SRP
R3: List | S3: Job Special | T3: List | U3: Job Special
O4: 92mm x 1.15 Head Track | T4: 10.17
C5: Plywood Nogging | D5: 12mm Plywood | E5: 1 | F5: Sheet | G5: 75 | H5: =E5*G5 -> 75 | O5: 92mm x 1.15 DHT | P5: 375 l/m | T5: 11.4
D6: Nogging Brackets | E6: 14 | F6: No | G6: 4.34 | H6: =E6*G6 -> 60.76 | O6: 92mm x 0.75 DHT | T6: 6.13
D7: Fixings | E7: 1 | F7: item | G7: 2.5 | H7: =E7*G7 -> 2.5 | O7: 92mm x 0.75 Stud | P7: 4500 l/m | T7: 5.23
H8: =SUM(H5:H7) -> 138.26 | O8: 92mm x 0.70 Base Track | P8: 375 l/m | T8: 5.23
O9: 92mm Nogging Track | T9: 8.48
O10: 64mm x 0.75 DHT | T10: 5.67
O11: 64mm Nogging Track | T11: 6.5
O12: 64mm x 0.55 Head Track | T12: 2.89
O13: 64mm x 0.70 Stud | T13: 4.71
O14: BC90 Brackets | T14: 4.85
O15: BC45 Brackets | T15: 4.85
O16: 90 x 45 SG8 | Q16: 3.8
O17: Hilti Hus 4-H 70mm | Q17: 1.7
C20: P10 or P11 - Bulkhead Structure Make Up | D20: 1 | E20: LENGTH | F20: 1 | G20: HEIGHT | H20: =Partitions!H11 -> 50
P21: Rate | Q21: Wastage | S21: Loadin
Q22: 1.05
C23: 92 x 1.15 Head Track | D23: =D20 -> 1 | E23: m | F23: 0.15 | G23: =D23*F23 -> 0.15 | H23: =$H$20*F23 -> 7.5 | I23: =G23*$H$20 -> 7.5 | J23: =T23 -> 10.9285 | K23: =D23*J23 -> 10.9285 | L23: =SUM(I23,K23) -> 18.4285 | M23: =L23/D23 -> 18.4285 | N23: =D23*M23 -> 18.4285 | P23: =T4 -> 10.17 | Q23: =P23*$Q$22 -> 10.6785 | R23: =Q23 -> 10.6785 | S23: 0.25 | T23: =SUM(R23:S23) -> 10.9285
C24: Hilti Hus 4-H 70mm Fixing to above | D24: =D23/0.6 -> 1.6666667 | E24: no | F24: 0.1 | G24: =D24*F24 -> 0.16666667 | H24: =$H$20*F24 -> 5 | I24: =G24*$H$20 -> 8.3333333 | J24: =Q17 -> 1.7 | K24: =D24*J24 -> 2.8333333 | L24: =SUM(I24,K24) -> 11.166667 | M24: =L24/D24 -> 6.7 | N24: =D24*M24 -> 11.166667 | Q24: =P24*$Q$22 -> 0 | R24: =Q24 -> 0 | T24: =SUM(R24:S24) -> 0
C25: 92 x 0.75 Dropper Stud | D25: =(D20/0.6)*F20 -> 1.6666667 | E25: m | F25: 0.1 | G25: =D25*F25 -> 0.16666667 | H25: =$H$20*F25 -> 5 | I25: =G25*$H$20 -> 8.3333333 | J25: =T25 -> 5.7415 | K25: =D25*J25 -> 9.5691667 | L25: =SUM(I25,K25) -> 17.9025 | M25: =L25/D25 -> 10.7415 | N25: =D25*M25 -> 17.9025 | P25: =T7 -> 5.23 | Q25: =P25*$Q$22 -> 5.4915 | R25: =Q25 -> 5.4915 | S25: 0.25 | T25: =SUM(R25:S25) -> 5.7415
C27: 64mm x 0.55 Head Track | D27: =D20 -> 1 | E27: m | F27: 0.15 | G27: =D27*F27 -> 0.15 | H27: =$H$20*F27 -> 7.5 | I27: =G27*$H$20 -> 7.5 | J27: =T27 -> 3.2845 | K27: =D27*J27 -> 3.2845 | L27: =SUM(I27,K27) -> 10.7845 | M27: =L27/D27 -> 10.7845 | N27: =D27*M27 -> 10.7845 | P27: =T12 -> 2.89 | Q27: =P27*$Q$22 -> 3.0345 | R27: =Q27 -> 3.0345 | S27: 0.25 | T27: =SUM(R27:S27) -> 3.2845
C28: Hilti Hus 4-H 70mm Fixing to above | D28: =D27/0.6 -> 1.6666667 | E28: no | F28: 0.1 | G28: =D28*F28 -> 0.16666667 | H28: =$H$20*F28 -> 5 | I28: =G28*$H$20 -> 8.3333333 | J28: =Q17 -> 1.7 | K28: =D28*J28 -> 2.8333333 | L28: =SUM(I28,K28) -> 11.166667 | M28: =L28/D28 -> 6.7 | N28: =D28*M28 -> 11.166667 | Q28: =P28*$Q$22 -> 0 | R28: =Q28 -> 0 | T28: =SUM(R28:S28) -> 0
C29: 64 x 0.70 Dropper Stud | D29: =(D20/0.6)*F20 -> 1.6666667 | E29: m | F29: 0.1 | G29: =D29*F29 -> 0.16666667 | H29: =$H$20*F29 -> 5 | I29: =G29*$H$20 -> 8.3333333 | J29: =T29 -> 5.1955 | K29: =D29*J29 -> 8.6591667 | L29: =SUM(I29,K29) -> 16.9925 | M29: =L29/D29 -> 10.1955 | N29: =D29*M29 -> 16.9925 | P29: =T13 -> 4.71 | Q29: =P29*$Q$22 -> 4.9455 | R29: =Q29 -> 4.9455 | S29: 0.25 | T29: =SUM(R29:S29) -> 5.1955
C31: 92 x 0.75 Bridge Stud | D31: =(D20/0.6)*0.242 -> 0.40333333 | E31: m | F31: 0.1 | G31: =D31*F31 -> 0.040333333 | H31: =$H$20*F31 -> 5 | I31: =G31*$H$20 -> 2.0166667 | J31: =T31 -> 5.7415 | K31: =D31*J31 -> 2.3157383 | L31: =SUM(I31,K31) -> 4.332405 | M31: =L31/D31 -> 10.7415 | N31: =D31*M31 -> 4.332405 | P31: =T7 -> 5.23 | Q31: =P31*$Q$22 -> 5.4915 | R31: =Q31 -> 5.4915 | S31: 0.25 | T31: =SUM(R31:S31) -> 5.7415
C32: BC90 Brackets | D32: =(D20/0.6)*2 -> 3.3333333 | E32: no | F32: 0.15 | G32: =D32*F32 -> 0.5 | H32: =$H$20*F32 -> 7.5 | I32: =G32*$H$20 -> 25 | J32: =T32 -> 5.0925 | K32: =D32*J32 -> 16.975 | L32: =SUM(I32,K32) -> 41.975 | M32: =L32/D32 -> 12.5925 | N32: =D32*M32 -> 41.975 | P32: =T14 -> 4.85 | Q32: =P32*$Q$22 -> 5.0925 | R32: =Q32 -> 5.0925 | T32: =SUM(R32:S32) -> 5.0925
C34: 92 x 0.70 Boxed Stud Lintel | D34: =D20 -> 1 | E34: m | F34: 0.2 | G34: =D34*F34 -> 0.2 | H34: =$H$20*F34 -> 10 | I34: =G34*$H$20 -> 10 | J34: =T34*2 -> 11.983 | K34: =D34*J34 -> 11.983 | L34: =SUM(I34,K34) -> 21.983 | M34: =L34/D34 -> 21.983 | N34: =D34*M34 -> 21.983 | O34: Double Rate | P34: =T7 -> 5.23 | Q34: =P34*$Q$22 -> 5.4915 | R34: =Q34 -> 5.4915 | S34: 0.5 | T34: =SUM(R34:S34) -> 5.9915
C35: 92 x 1.15 DHT | D35: =D20 -> 1 | E35: m | F35: 0.1 | G35: =D35*F35 -> 0.1 | H35: =$H$20*F35 -> 5 | I35: =G35*$H$20 -> 5 | J35: =T35 -> 12.22 | K35: =D35*J35 -> 12.22 | L35: =SUM(I35,K35) -> 17.22 | M35: =L35/D35 -> 17.22 | N35: =D35*M35 -> 17.22 | P35: =T5 -> 11.4 | Q35: =P35*$Q$22 -> 11.97 | R35: =Q35 -> 11.97 | S35: 0.25 | T35: =SUM(R35:S35) -> 12.22
C37: 90 x 45 SG8 Timber Support | D37: =D20 -> 1 | E37: m | F37: 0.17 | G37: =D37*F37 -> 0.17 | H37: =$H$20*F37 -> 8.5 | I37: =G37*$H$20 -> 8.5 | J37: =T37 -> 4.24 | K37: =D37*J37 -> 4.24 | L37: =SUM(I37,K37) -> 12.74 | M37: =L37/D37 -> 12.74 | N37: =D37*M37 -> 12.74 | P37: =Q16 -> 3.8 | Q37: =P37*$Q$22 -> 3.99 | R37: =Q37 -> 3.99 | S37: 0.25 | T37: =SUM(R37:S37) -> 4.24
C39: Teks | D39: =(D20/0.6)*30 -> 50 | E39: no | F39: 0 | G39: =D39*F39 -> 0 | H39: =$H$20*F39 -> 0 | I39: =G39*$H$20 -> 0 | J39: 0.026 | K39: =D39*J39 -> 1.3 | L39: =SUM(I39,K39) -> 1.3 | M39: =L39/D39 -> 0.026 | N39: =D39*M39 -> 1.3 | Q39: =P39*$Q$22 -> 0 | R39: =Q39 -> 0 | T39: =SUM(R39:S39) -> 0
G41: =SUM(G23:G40) -> 1.977 | I41: =SUM(I23:I40) -> 98.85 | K41: =SUM(K23:K40) -> 87.141738 | N41: =SUM(N23:N40) -> 185.99174
C43: P12 - Bulkhead Structure Make Up | D43: 1 | E43: LENGTH | F43: 1 | G43: HEIGHT | H43: =Partitions!H11 -> 50
P44: Rate | Q44: Wastage | S44: Loadin
Q45: 1.05
C46: 92 x 1.15 Head Track | D46: =D43 -> 1 | E46: m | F46: 0.15 | G46: =D46*F46 -> 0.15 | H46: =$H$43*F46 -> 7.5 | I46: =G46*$H$20 -> 7.5 | J46: =T46 -> 10.9285 | K46: =D46*J46 -> 10.9285 | L46: =SUM(I46,K46) -> 18.4285 | M46: =L46/D46 -> 18.4285 | N46: =D46*M46 -> 18.4285 | P46: =T4 -> 10.17 | Q46: =P46*$Q$22 -> 10.6785 | R46: =Q46 -> 10.6785 | S46: 0.25 | T46: =SUM(R46:S46) -> 10.9285
C47: Hilti Hus 4-H 70mm Fixing to above | D47: =D43/0.6 -> 1.6666667 | E47: no | F47: 0.1 | G47: =D47*F47 -> 0.16666667 | H47: =$H$43*F47 -> 5 | I47: =G47*$H$20 -> 8.3333333 | J47: =Q17 -> 1.7 | K47: =D47*J47 -> 2.8333333 | L47: =SUM(I47,K47) -> 11.166667 | M47: =L47/D47 -> 6.7 | N47: =D47*M47 -> 11.166667 | Q47: =P47*$Q$22 -> 0 | R47: =Q47 -> 0 | T47: =SUM(R47:S47) -> 0
C48: 92 x 0.75 Dropper Stud | D48: =(D43/0.6)*F43 -> 1.6666667 | E48: m | F48: 0.1 | G48: =D48*F48 -> 0.16666667 | H48: =$H$43*F48 -> 5 | I48: =G48*$H$20 -> 8.3333333 | J48: =T48 -> 5.7415 | K48: =D48*J48 -> 9.5691667 | L48: =SUM(I48,K48) -> 17.9025 | M48: =L48/D48 -> 10.7415 | N48: =D48*M48 -> 17.9025 | P48: =T7 -> 5.23 | Q48: =P48*$Q$22 -> 5.4915 | R48: =Q48 -> 5.4915 | S48: 0.25 | T48: =SUM(R48:S48) -> 5.7415
C50: BC90 Brackets | D50: =D43/0.6 -> 1.6666667 | E50: no | F50: 0.07 | G50: =D50*F50 -> 0.11666667 | H50: =$H$43*F50 -> 3.5 | I50: =G50*$H$20 -> 5.8333333 | J50: =T50 -> 5.0925 | K50: =D50*J50 -> 8.4875 | L50: =SUM(I50,K50) -> 14.320833 | M50: =L50/D50 -> 8.5925 | N50: =D50*M50 -> 14.320833 | P50: =T14 -> 4.85 | Q50: =P50*$Q$22 -> 5.0925 | R50: =Q50 -> 5.0925 | T50: =SUM(R50:S50) -> 5.0925
C52: BC45 Brackets | D52: =(D43/1.8)*2 -> 1.1111111 | E52: no | F52: 0.07 | G52: =D52*F52 -> 0.077777778 | H52: =$H$43*F52 -> 3.5 | I52: =G52*$H$20 -> 3.8888889 | J52: =T52 -> 5.0925 | K52: =D52*J52 -> 5.6583333 | L52: =SUM(I52,K52) -> 9.5472222 | M52: =L52/D52 -> 8.5925 | N52: =D52*M52 -> 9.5472222 | P52: =T15 -> 4.85 | Q52: =P52*$Q$22 -> 5.0925 | R52: =Q52 -> 5.0925 | T52: =SUM(R52:S52) -> 5.0925
...

Sheet Insulation
B1: =Summary!B1 -> Ceilings Unlimited
B2: =Summary!B2 -> Craigs Investment Partners - Fitout
B3: =Summary!B3 -> Tauranga
B6: =Summary!B5 -> 46043
B9: =Summary!B121 -> Insulation
H11: 45
A12: Item | B12: Description | C12: Qty | D12: Unit | E12: Constant | F12: Constant X Unit = Total HRS | G12: $ Lab per Unit | H12: Total Labour | I12: Materials per Unit | J12: Total Materials | K12: Total Labour & Materials | L12: Total Labour & Materials Per Unit | M12: Total | N12: % Complete | O12: Claim
B14: Ceiling Insulation:
B16: Level 4:
B18: (C-01B) | C18: Nil, By Others Basebuid
B19: (C-02) R1.8 Autex Sound Solution on top | C19: 45 | D19: m2 | E19: 0.15 | F19: =C19*E19 -> 6.75 | G19: =$H$11*E19 -> 6.75 | H19: =F19*$H$11 -> 303.75 | I19: =$X$26 -> 8.8710241 | J19: =C19*I19 -> 399.19608 | K19: =SUM(H19,J19) -> 702.94608 | L19: =K19/C19 -> 15.621024 | M19: =C19*L19 -> 702.94608 | N19: 0 | O19: =M19*N19 -> 0
B20: (C-04) 50mm Autex Quietpsace | C20: Nil, By Others
V22: Freight
B23: Level 5: | V23: 1.05
B25: (C-01B) | C25: Nil, By Others Basebuid | Q25: =SUM(C45,C49,C51,C54,C57,C60,C65,C69,C71,C73,C76,C82,C84,C86,C88,C90,C92,C92) -> 1149 | R25: Walls | S25: 47 | T25: 210.37 | U25: Bales | V25: =T25*$V$23 -> 220.8885 | W25: =S25*V25 -> 10381.76 | X25: =W25/Q25 -> 9.0354739
B26: (C-04) 50mm Autex Quietpsace | C26: Nil, By Others | Q26: =SUM(C25,C34) -> 249 | R26: Ceiling | S26: 10 | T26: 210.37 | U26: Bales | V26: =T26*$V$23 -> 220.8885 | W26: =S26*V26 -> 2208.885 | X26: =W26/Q26 -> 8.8710241
Q27: 121 | R27: Baffle | T27: 78.67 | U27: Roll | V27: =T27*$V$23 -> 82.6035 | W27: =Q27*V27 -> 9995.0235 | X27: =W27/Q29 -> 75.719875
B29: Level 6: | Q29: =SUM(C47,C52,C55,C58,C67,C74,C77) -> 132
B31: (C-01A) | C31: Nil, By Others Basebuid
B32: (C-01B) | C32: Nil, By Others Basebuid
B33: (C-02) R1.8 Autex Sound Solutuion on top | C33: 4 | D33: m2 | E33: 0.15 | F33: =C33*E33 -> 0.6 | G33: =$H$11*E33 -> 6.75 | H33: =F33*$H$11 -> 27 | I33: =$X$26 -> 8.8710241 | J33: =C33*I33 -> 35.484096 | K33: =SUM(H33,J33) -> 62.484096 | L33: =K33/C33 -> 15.621024 | M33: =C33*L33 -> 62.484096 | N33: 0 | O33: =M33*N33 -> 0
B34: (C-03) R1.8 Autex Sound Solutuion on top | C34: 249 | D34: m2 | E34: 0.15 | F34: =C34*E34 -> 37.35 | G34: =$H$11*E34 -> 6.75 | H34: =F34*$H$11 -> 1680.75 | I34: =$X$26 -> 8.8710241 | J34: =C34*I34 -> 2208.885 | K34: =SUM(H34,J34) -> 3889.635 | L34: =K34/C34 -> 15.621024 | M34: =C34*L34 -> 3889.635 | N34: 0 | O34: =M34*N34 -> 0
B35: (C-08) 50mm Autex Quietspace Black Above Mesh | C35: Refer Suspended Ceiling Trade
B36: (C-09) R1.8 Autex Sound Solutuion on top | C36: 36 | D36: m2 | E36: 0.15 | F36: =C36*E36 -> 5.4 | G36: =$H$11*E36 -> 6.75 | H36: =F36*$H$11 -> 243 | I36: =$X$26 -> 8.8710241 | J36: =C36*I36 -> 319.35687 | K36: =SUM(H36,J36) -> 562.35687 | L36: =K36/C36 -> 15.621024 | M36: =C36*L36 -> 562.35687 | N36: 0 | O36: =M36*N36 -> 0
B37: (C-10) 50mm Autex Quietspace Black Above Mesh | C37: Refer Suspended Ceiling Trade
B38: C-11) AAB 35-50 | C38: 204 | D38: m2 | E38: 0.15 | F38: =C38*E38 -> 30.6 | G38: =$H$11*E38 -> 6.75 | H38: =F38*$H$11 -> 1377 | I38: 14.75 | J38: =C38*I38 -> 3009 | K38: =SUM(H38,J38) -> 4386 | L38: =K38/C38 -> 21.5 | M38: =C38*L38 -> 4386 | N38: 0 | O38: =M38*N38 -> 0
B41: Wall and Baffle Stack Insulation:
B43: Level 4:
B45: (P-10) Autex R1.8 Sound Solution | C45: 4 | D45: m2 | E45: 0.12 | F45: =C45*E45 -> 0.48 | G45: =$H$11*E45 -> 5.4 | H45: =F45*$H$11 -> 21.6 | I45: =$X$25 -> 9.0354739 | J45: =C45*I45 -> 36.141896 | K45: =SUM(H45,J45) -> 57.741896 | L45: =K45/C45 -> 14.435474 | M45: =C45*L45 -> 57.741896 | N45: 0 | O45: =M45*N45 -> 0
B47: (P-11) Autex Baffle Block | C47: 23 | D47: m | E47: 0.7 | F47: =C47*E47 -> 16.1 | G47: =$H$11*E47 -> 31.5 | H47: =F47*$H$11 -> 724.5 | I47: =$X$27 -> 75.719875 | J47: =C47*I47 -> 1741.5571 | K47: =SUM(H47,J47) -> 2466.0571 | L47: =K47/C47 -> 107.21987 | M47: =C47*L47 -> 2466.0571 | N47: 0 | O47: =M47*N47 -> 0 | P47: 21
B49: (P-20A) Autex R1.8 Sound Solution | C49: 34 | D49: m2 | E49: 0.12 | F49: =C49*E49 -> 4.08 | G49: =$H$11*E49 -> 5.4 | H49: =F49*$H$11 -> 183.6 | I49: =$X$25 -> 9.0354739 | J49: =C49*I49 -> 307.20611 | K49: =SUM(H49,J49) -> 490.80611 | L49: =K49/C49 -> 14.435474 | M49: =C49*L49 -> 490.80611 | N49: 0 | O49: =M49*N49 -> 0
B51: (P-21S) Autex R1.8 Sound Solution | C51: 19 | D51: m2 | E51: 0.12 | F51: =C51*E51 -> 2.28 | G51: =$H$11*E51 -> 5.4 | H51: =F51*$H$11 -> 102.6 | J51: =C51*I51 -> 0 | K51: =SUM(H51,J51) -> 102.6 | L51: =K51/C51 -> 5.4 | M51: =C51*L51 -> 102.6 | N51: 0 | O51: =M51*N51 -> 0
